Workbook

Sheet 0_안내
A1: 반응형외피 · 1일차 경제성 자료
A2: 작성 | B2: 은미 (보고서·경제성·PM)
A3: 시트 구성 | B3: 1_입력값 / 2_단가조사 / 3_차폐·냉방환산 / 4_결정회의안건 / 5_1784운영규칙 / 6_태양궤적(혜연) / 7_공사비 / 8_시공전후 / 9_발주처이익 / 10_누적·민감도 / 11_인센티브 / 12_일정표
A4: 색 규칙 | B4: 노랑 = 팀이 입력·확정할 칸 / 회색 = 참고용 임시값(출처 확인 전)
A5: 중요 | B5: 임시값과 빈칸은 실제 조사 결과가 아닙니다. 출처를 확인하고 상태를 바꾼 뒤에만 보고서에 쓰세요. 2_단가조사의 숫자는 공개 자료로 확인되지 않아 제가 넣은 추정치입니다. 5_1784운영규칙과 6_태양궤적은 혜연의 자료입니다.
A6: 2일차 연결 | B6: 1_입력값이 모든 시트의 유일한 입력원이 되도록 공사비·시공전후·발주처이익 시트가 이 셀들을 참조하게 만듭니다
A7: 비교 대안 4개 | B7: 시공 전(일반 통유리) / 내부 반응형(그린팩토리형) / 외부 고정 / 외부 반응형(1784형). 내부 vs 외부는 내부·외부 반응형을, 고정 vs 반응형은 외부 고정·외부 반응형을 비교합니다.
A8: 반응형 추가 비용 | B8: 반응형(내부·외부)에는 수동 작동 앱 개발비(1회)와 앱 연 운영비가 들어갑니다. 외부 반응형은 루버 보호 유리(1784의 바깥 유리와 같은 개념)를 포함하는지 1_입력값 47행 스위치로 정합니다. 1784 자체는 비교 대안이 아니라 운영 검증용입니다.
A9: 인센티브 | B9: 11_인센티브: 신축(취득세·재산세 감면)과 리모델링(이자지원·재산세 감면) 시나리오. 기본은 꺼져 있고, 켜면 누적 비용과 손익분기에 반영됩니다. 감면율은 확인 필요한 가정값입니다.
A10: 2일차 시트 | B10: 7~10번 시트는 모두 1_입력값과 2_단가조사에 연결됩니다. 입력값 하나를 바꾸면 공사비, 시공 전후, 발주처 이익, 누적, 민감도가 함께 바뀝니다.
A11: 임시 테스트값 | B11: 주황색 칸(창 면적, 루버 면적, 일사량, 조명 사용량 등)은 계산이 되는지 보려고 제가 넣은 임시값입니다. 우정·혜연·서우의 실제 값으로 교체하기 전의 결과는 보고서에 쓰지 마세요.

Sheet 1_입력값
A1: No | B1: 구분 | C1: 입력값 | D1: 값 | E1: 단위 | F1: 설명 / 어디서 오나 | G1: 제공자 | H1: 상태
A2: 1 | B2: 위치 | C2: 위도 | D2: 37.35936 | E2: °N | F2: 그린팩토리(OSM). 1784는 37.35888 | G2: 혜연 | H2: 입력 (혜연 자료)
A3: 2 | B3: 위치 | C3: 경도 | D3: 127.10502 | E3: °E | F3: 그린팩토리(OSM). 1784는 127.10518 | G3: 혜연 | H3: 입력 (혜연 자료)
A4: 3 | B4: 위치 | C4: 대표일 | D4: 춘분 3/21 · 하지 6/21 · 추분 9/23 · 동지 12/21 | F4: 혜연은 4일을 제시. 계획서는 3일(하지·춘추분·동지) → 회의에서 확정 | G4: 전원 | H4: 혜연 제안, 확정 필요
A5: 4 | B5: 입면 | C5: 분석 입면 방위 | E5: ° (방위각) | F5: 북0 동90 남180 서270. 1784 외곽선은 정동서남북에 1° 이내 정렬(OSM) | G5: 전원 | H5: 회의 안건
A6: 5 | B6: 입면 | C6: 창(커튼월) 면적 - 루버 설치면 합계 | D6: =SUMPRODUCT(D53:D56,D57:D60) | E6: ㎡ | F6: 분석 입면 기준, Revit | G6: 우정 | H6: 루버 설치면 합계 (아래 53~60행)
A7: 6 | B7: 입면 | C7: 대표 실 면적 | E7: ㎡ | F7: 대표 실 조건표 | G7: 서우 | H7: 미입력
A8: 7 | B8: 루버 | C8: 외부 고정 루버 면적 | D8: =D6*D61 | E8: ㎡ | F8: Revit 일람표 | G8: 우정 | H8: 설치면 창 면적 × 루버 면적비
A9: 8 | B9: 루버 | C9: 외부 반응형 루버 면적 | D9: =D6*D61 | E9: ㎡ | F9: Revit 일람표 | G9: 우정 | H9: 설치면 창 면적 × 루버 면적비
A10: 9 | B10: 루버 | C10: 구동 유닛 수 (외부 반응형) | D10: =ROUND(D9/D62,0) | E10: 개 | F10: Revit 일람표 루버 개수 | G10: 우정 | H10: 루버 면적 ÷ 유닛당 면적
A11: 10 | B11: 루버 | C11: 내부 반응형 루버 면적 | D11: =D6*D61 | E11: ㎡ | F11: Revit 일람표 (내부 설치 루버) | G11: 우정 | H11: 설치면 창 면적 × 루버 면적비
A12: 11 | B12: 공사 | C12: 가설(곤돌라·고소작업) 일수 | D12: 60 | E12: 일 | F12: 외부 설치 가설 일수 (곤돌라·고소작업) | G12: 은미 | H12: 임시 테스트값 (실제값으로 교체)
A13: 12 | B13: 공사 | C13: 설계·감리 비율 | D13: ='2_단가조사'!F9 | E13: % (직접공사비) | F13: 단가조사 시트 | G13: 은미 | H13: 단가조사 기준값 연결
A14: 13 | B14: 공사 | C14: 예비비 비율 | D14: ='2_단가조사'!F10 | E14: % (직접공사비) | F14: 단가조사 시트 | G14: 은미 | H14: 단가조사 기준값 연결
A15: 14 | B15: 경제성 | C15: 전기요금 단가 | D15: ='2_단가조사'!F15 | E15: 원/kWh | F15: 단가조사 시트 기준값 | G15: 은미 | H15: 단가조사 기준값 연결
A16: 15 | B16: 경제성 | C16: 전기요금 연 인상률 | D16: ='2_단가조사'!F16 | E16: %/년 | F16: 민감도용 | G16: 은미 | H16: 단가조사 기준값 연결
A17: 16 | B17: 경제성 | C17: 루버 수명 | D17: ='2_단가조사'!F13 | E17: 년 | F17: 누적 순이익 기간 | G17: 은미 | H17: 단가조사 기준값 연결
A18: 17 | B18: 경제성 | C18: 연 유지관리비율 | D18: ='2_단가조사'!F11 | E18: % (공사비) | F18: 유지비 가정 | G18: 은미 | H18: 단가조사 기준값 연결(외부 고정 루버)
A19: 18 | B19: 경제성 | C19: 할인율 (선택) | E19: % | F19: 단순 회수기간이면 생략 | G19: 은미 | H19: 결정 필요
A20: 19 | B20: 냉방 | C20: 냉방 COP | D20: 3.5 | E20: - | F20: 팀 EnergyPlus 가정 (v9) | G20: 팀 | H20: 팀 v9
A21: 20 | B21: 냉방 | C21: 냉방 부하 / 창 일사 (kWh/kWh) | D21: 1.13 | E21: - | F21: 창에 닿는 일사 1 kWh 감소 → 냉방 부하 1.13 kWh 감소. 팀 EnergyPlus 민감도 (1784 9층 서남 모서리 방). 다른 건물은 간이 추정 | G21: 팀 | H21: 팀 v9
A22: 21 | B22: 냉방 | C22: 대안별 일사량(연 환산) | D22: 아래 36~39행 (루버 설치면 평균) | E22: kWh/㎡·년 | F22: 혜연 GH 결과(대표일→연간) | G22: 혜연 | H22: 4일차 수령
A23: 22 | B23: 조명 | C23: 대안별 조명 사용량 | D23: 아래 40~43행 | E23: kWh/년 | F23: 서우 Honeybee 결과 | G23: 서우 | H23: 4일차 수령
A24: 23 | B24: 확장 | C24: 반사광 진행 여부 | E24: 예/아니오 | F24: 5일차 아침 판단 | G24: 전원 | H24: 5일차
A25: 24 | B25: 운영규칙 | C25: 컷오프(춘분/하지/추분/동지) | D25: 30 / 60 / 45 / 30 | E25: ° | F25: 혜연 팀 가정값. 5_1784운영규칙 시트 참조 | G25: 혜연 | H25: 가정 (±15° 민감도 예정)
A26: 25 | B26: 운영규칙 | C26: 최소 태양고도 | D26: 5 | E26: ° | F26: 이 고도 미만이면 열림 | G26: 혜연 | H26: 가정
A27: 26 | B27: 운영규칙 | C27: 창면적비 | D27: 40~50 | E27: % | F27: 삼우TV 영상 2:17 (적정 창면적비) | G27: 혜연 | H27: 영상 근거
A28: 27 | B28: 운영규칙 | C28: 시간 기준 | D28: UTC+9 | F28: 한국 표준시, 일광절약 없음 | G28: 혜연 | H28: 확정
C30: 2일차 추가 입력
C31: 단가 배율 (민감도) | D31: 1 | E31: 배수 | F31: 공사비 전체에 곱함 | H31: 기본값
C32: 전기요금 배율 (민감도) | D32: 1 | E32: 배수 | F32: 에너지 비용에 곱함 | H32: 기본값
C33: 유지비 배율 (민감도) | D33: 1 | E33: 배수 | F33: 유지관리비에 곱함 | H33: 기본값
C34: 연 유지관리비율(반응형) | D34: ='2_단가조사'!F12 | E34: % (공사비) | F34: 내부·외부 반응형에 적용 · 단가조사 기준값 연결 | H34: 단가조사 기준값 연결
C35: 전동 구동장치 수명 (보호 유리 안 · 실내) | D35: ='2_단가조사'!F14 | E35: 년 | F35: 교체비 반영은 회의 안건 9번(현재 미반영) | H35: 단가조사 기준값 연결
C36: 일사량 - 시공 전(일반 통유리) | D36: ='14_Radiance(팀)'!C92 | E36: kWh/㎡ (냉방기 6~9월, 1784 1~28층 평균, 창 면적 가중) | F36: 혜연 GH 결과(연 환산) · 동·남·서면 창 면적 가중 평균, 북면 제외 | H36: 임시 테스트값 (실제값으로 교체)
C37: 일사량 - 내부 반응형 | D37: ='14_Radiance(팀)'!C92-(1-0.55)*('14_Radiance(팀)'!C92-'14_Radiance(팀)'!E92) | E37: kWh/㎡ (냉방기, 1~28층 평균) = 통유리 − 0.45 × (통유리 − 외부 반응형) | F37: 혜연 GH 결과 | H37: 임시 테스트값 (실제값으로 교체)
C38: 일사량 - 외부 고정 | D38: ='14_Radiance(팀)'!D92 | E38: kWh/㎡ (냉방기 6~9월, 1784 1~28층 평균, 창 면적 가중) | F38: 혜연 GH 결과 | H38: 임시 테스트값 (실제값으로 교체)
C39: 일사량 - 외부 반응형 | D39: ='14_Radiance(팀)'!E92 | E39: kWh/㎡ (냉방기 6~9월, 1784 1~28층 평균, 창 면적 가중) | F39: 혜연 GH 결과 | H39: 임시 테스트값 (실제값으로 교체)
C40: 조명 사용량 - 시공 전(일반 통유리) | D40: 38000 | E40: kWh/년 | F40: 서우 Honeybee 결과 | H40: 임시 테스트값 (실제값으로 교체)
C41: 조명 사용량 - 내부 반응형 | D41: 42000 | E41: kWh/년 | F41: 서우 Honeybee 결과 | H41: 임시 테스트값 (실제값으로 교체)
...

Sheet 2_단가조사
A1: No | B1: 구분 | C1: 항목 | D1: 단위 | E1: 최소 | F1: 기준 | G1: 최대 | H1: 출처 (문서명·URL·날짜) | I1: 어디서 찾나 (조사 힌트) | J1: 상태
A2: 1 | B2: ① 자재 | C2: 알루미늄 외부 루버 자재 | D2: 원/㎡ | E2: 150000 | F2: 250000 | G2: 400000 | H2: 추정 (근거 없음, 학원 프로젝트 가정) | I2: 확인하려면: 시공업체 견적, 나라장터 가격정보, 물가정보 자재가격 | J2: 추정
A3: 2 | B3: ① 자재 | C3: 고정 루버 지지 프레임·부속 | D3: 원/㎡ | E3: 40000 | F3: 70000 | G3: 120000 | H3: 추정 (근거 없음, 학원 프로젝트 가정) | I3: 위와 동일(루버 단가에 포함인지 확인) | J3: 추정
A4: 3 | B4: ② 구동·제어 | C4: 구동 유닛(모터·액추에이터) | D4: 원/유닛 | E4: 300000 | F4: 600000 | G4: 1200000 | H4: 추정 (근거 없음, 학원 프로젝트 가정) | I4: 제조사/대리점 견적. 공개 자료 거의 없음 | J4: 추정
A5: 4 | B5: ② 구동·제어 | C5: 센서·제어 시스템(BMS 연동) | D5: 원/식 | E5: 10000000 | F5: 30000000 | G5: 60000000 | H5: 추정 (근거 없음, 학원 프로젝트 가정) | I5: 분석 입면 1개 기준 가정 | J5: 추정
A6: 5 | B6: ③ 설치 | C6: 루버 설치 시공 단가 | D6: 원/㎡ | E6: 80000 | F6: 130000 | G6: 200000 | H6: 추정 (근거 없음, 학원 프로젝트 가정) | I6: 건설공사 표준품셈, 시공업체 견적 | J6: 추정
A7: 6 | B7: ④ 가설·장비 | C7: 곤돌라 임대·설치 | D7: 원/일 | E7: 400000 | F7: 700000 | G7: 1000000 | H7: 추정 (근거 없음, 학원 프로젝트 가정) | I7: 임대업체 견적 | J7: 추정
A8: 7 | B8: ④ 가설·장비 | C8: 고소작업차 | D8: 원/일 | E8: 400000 | F8: 600000 | G8: 900000 | H8: 추정 (근거 없음, 학원 프로젝트 가정) | I8: 임대업체 견적 | J8: 추정
A9: 8 | B9: ⑤ 간접 | C9: 설계·감리비 | D9: % (직접공사비) | E9: 5 | F9: 8 | G9: 12 | H9: 추정 (근거 없음, 학원 프로젝트 가정) | I9: 건축사 대가기준 등 요율 확인 | J9: 추정
A10: 9 | B10: ⑤ 간접 | C10: 예비비 | D10: % (직접공사비) | E10: 3 | F10: 5 | G10: 10 | H10: 추정 (근거 없음, 학원 프로젝트 가정) | J10: 추정
A11: 10 | B11: 운영 | C11: 연 유지관리비율(고정 루버, 루버 시스템비 대비) | D11: % (날·프레임·설치비) | E11: 0.5 | F11: 1 | G11: 2 | H11: 일반 건물 연 유지비 2~4%(재조달가 대비)의 낮은 쪽 — 움직이는 부분 없음 (가정) | J11: 추정
A12: 11 | B12: 운영 | C12: 연 유지관리비율(반응형 루버, 루버 시스템비 대비) | D12: % (날·프레임·구동·설치비) | E12: 2 | F12: 3 | G12: 4 | H12: 일반 건물 연 유지비 2~4%(재조달가 대비, 상업 건물 가이드라인)의 중간 (가정) | I12: 모터·센서 점검·교체 포함 가정, 고정보다 높게 | J12: 추정
A13: 12 | B13: 운영 | C13: 루버 수명(고정) | D13: 년 | E13: 25 | F13: 30 | G13: 40 | H13: 추정 (근거 없음, 학원 프로젝트 가정) | I13: 알루미늄 외장재 내구연한 | J13: 추정
A14: 13 | B14: 운영 | C14: 전동 구동장치 수명 (보호 유리 안 · 실내) | D14: 년 | E14: 7 | F14: 10 | G14: 15 | H14: 제조사 모터 보증 실내 10년 참고 (가정) | I14: 수명 중 교체비 반영 여부는 회의 안건 9번 | J14: 추정
A15: 14 | B15: 전기요금 | C15: 전기요금 단가 | D15: 원/kWh | E15: 130 | F15: 150 | G15: 170 | H15: 최대값 170: 증권사 리포트의 산업용 평균 보도(2025 4Q)·참고. 최소·기준은 추정 | I15: 한전 사이버지점 요금표로 확인 가능. 건물 계약종별(일반용/산업용) 결정 필요 | J15: 일부 참고
A16: 15 | B16: 전기요금 | C16: 전기요금 연 인상률 | D16: %/년 | E16: 2 | F16: 4 | G16: 6 | H16: 추정 (근거 없음, 학원 프로젝트 가정) | J16: 추정
A17: 16 | B17: ① 자재(내부) | C17: 내부 반응형 루버 자재 | D17: 원/㎡ | E17: 200000 | F17: 350000 | G17: 600000 | H17: 추정 (근거 없음, 학원 프로젝트 가정) | I17: 내부 설치형 전동 루버(그린팩토리형) 가정. 제조사 견적 필요 | J17: 추정
A18: 17 | B18: ③ 설치(내부) | C18: 내부 루버 설치 시공 단가 | D18: 원/㎡ | E18: 60000 | F18: 100000 | G18: 160000 | H18: 추정 (근거 없음, 학원 프로젝트 가정) | I18: 비계·곤돌라 없이 내부에서 시공한다고 가정 | J18: 추정
A19: 18 | B19: ⑥ 소프트웨어 | C19: 수동 작동 앱 개발비 (앱+서버, 1회) | D19: 원/식 | E19: 20000000 | F19: 40000000 | G19: 80000000 | H19: 추정 (근거 없음, 학원 프로젝트 가정) | I19: 반응형 루버를 수동으로도 조작하는 앱. 개발사 견적 필요 | J19: 추정
A20: 19 | B20: ⑥ 소프트웨어 | C20: 앱 연 운영·유지 (서버·업데이트) | D20: 원/년 | E20: 2000000 | F20: 4000000 | G20: 8000000 | H20: 추정 (근거 없음, 학원 프로젝트 가정) | I20: 서버, 보안 업데이트, 문의 대응 포함 가정 | J20: 추정
A21: 20 | B21: ⑦ 보호 유리 | C21: 외부 루버 보호 유리 (외측 유리 스킨, 프레임 포함) | D21: 원/㎡ | E21: 350000 | F21: 500000 | G21: 800000 | H21: 추정 (근거 없음, 학원 프로젝트 가정) | I21: 외부 루버를 바람·비·오염으로부터 보호하는 바깥 유리. 1784의 바깥 저반사 유리와 같은 개념. 견적 필요 | J21: 추정
B23: 메모 | C23: 반응형(전동) 외부 루버는 공개 단가가 거의 없습니다. 표의 모든 숫자는 근거 없는 추정입니다(학원 프로젝트 가정). 실제 견적을 얻으면 숫자와 출처를 교체하고 상태를 바꾸세요. 민감도(±30%)에서 결론이 유지되는지 보완합니다.
A25: 21 | B25: 운영 | C25: 전동 구동장치 수명 (바깥 노출) | D25: 년 | E25: 3 | F25: 5 | G25: 8 | H25: 제조사 모터 보증 실외 5년 참고 (가정)
A26: 22 | B26: 운영 | C26: 보호 유리 청소·점검 | D26: % (유리값/년) | E26: 0.5 | F26: 1 | G26: 2 | H26: 추정 (가정)

Sheet 3_차폐·냉방환산
A1: 냉방 환산 방법 (간이)
A2: ① 일사 취득열(kWh/년) = 입사 일사량(kWh/㎡·년) × 창 면적(㎡) × 유리 SHGC × 차양계수
A3: ② 냉방 전력(kWh/년) = 일사 취득열 ÷ COP ③ 냉방 전기요금(원/년) = 냉방 전력 × 전기요금 단가
A4: ※ 정밀 시뮬레이션이 아니라 세 대안을 같은 방식으로 비교하는 상대 비교입니다.
A6: 대안 | B6: 차양계수 최소 | C6: 차양계수 기준 | D6: 차양계수 최대 | E6: 출처 / 비고 | F6: 상태
A7: 시공 전 (일반 통유리) | B7: 1 | C7: 1 | D7: 1 | E7: [참고 범위·미검증] 내부 블라인드가 외부 장치보다 차폐가 약하다는 순서는 일반적이나 수치는 문헌(ASHRAE, KS L 9107, 국내 외부차양 실측 논문)에서 확인해 교체 | F7: 참고값
A8: 내부 반응형 루버 | B8: 0.45 | C8: 0.55 | D8: 0.65 | E8: [참고 범위·미검증] 내부 블라인드가 외부 장치보다 차폐가 약하다는 순서는 일반적이나 수치는 문헌(ASHRAE, KS L 9107, 국내 외부차양 실측 논문)에서 확인해 교체 | F8: 참고값
A9: 외부 고정 루버 | B9: 0.2 | C9: 0.3 | D9: 0.4 | E9: [참고 범위·미검증] 내부 블라인드가 외부 장치보다 차폐가 약하다는 순서는 일반적이나 수치는 문헌(ASHRAE, KS L 9107, 국내 외부차양 실측 논문)에서 확인해 교체 | F9: 참고값
A10: 외부 반응형 루버 | B10: 0.15 | C10: 0.25 | D10: 0.35 | E10: [참고 범위·미검증] 내부 블라인드가 외부 장치보다 차폐가 약하다는 순서는 일반적이나 수치는 문헌(ASHRAE, KS L 9107, 국내 외부차양 실측 논문)에서 확인해 교체 | F10: 참고값
A12: 이중계산 주의 | E12: 혜연의 일사량이 루버 기하까지 반영한 값이면 차양계수를 또 곱하면 이중계산입니다. 결정회의 안건 6번에서 정의하세요.
A14: ※ 실제 계산은 8_시공전후 시트에서 이 차양계수 표(기준 열)를 가져다 씁니다.

Sheet 4_결정회의안건
A1: No | B1: 안건 | C1: 논의할 것 / 제안안 | D1: 필요 자료 | E1: 담당 | F1: 결정 결과
A2: 1 | B2: 입력값 목록 | C2: 1_입력값 시트 항목이 빠짐없는지, 누가 어떤 값을 언제 주는지 확인 | D2: 1_입력값 시트 | E2: 은미 진행
A3: 2 | B3: 분석 입면 | C3: 그린팩토리에서 어느 입면(방위)을 분석할지. 일사가 뚜렷한 입면 권장. 범용 시연에서 동·남·서향으로 돌릴 수 있는 직사각형 입면인지도 확인 | D3: 입면 사진, 배치도 | E3: 우정·혜연
A4: 3 | B4: 대표 실 | C4: 분석 입면에 면한 사무 공간 1개, 창측·중간·안쪽 3구역 | D4: 실 면적, 층고 | E4: 서우
A5: 4 | B5: 대표일 3개 vs 4개 | C5: 계획서는 3일(하지·춘추분·동지)인데 혜연은 춘분 3/21·하지 6/21·추분 9/23·동지 12/21 4일로 계산함 → 4일로 갈지 확정, 연간 환산 가중치(각 대표일이 약 3개월 대표) 정의 | D5: 가중치 합의 | E5: 혜연·서우
A6: 5 | B6: 대안 4개 정의 | C6: 시공 전(일반 통유리) / 내부 반응형(그린팩토리형) / 외부 고정(고정 각도, 루버 간격·깊이) / 외부 반응형(1784 규칙). 고정 각도 기준이 정해져야 물량이 나옴. 내부 반응형의 공사비를 신설 기준으로 잡을지 확인 | D6: 1784 모듈 치수, 루버 패밀리 | E6: 우정·혜연
A7: 6 | B7: 차양계수 이중계산 방지 | C7: 혜연의 일사량이 루버 차폐를 이미 반영하는지, 차양계수는 무엇에만 적용할지 | D7: 3_차폐·냉방환산 시트 | E7: 혜연·은미
A8: 7 | B8: 데이터 전달 형식 | C8: 파일 하나에 주인 한 명, 파일 사이는 CSV. 열 이름·단위(예: kWh/㎡·년), 파일명 규칙, 전달 시점(3일 저녁 관통) | D8: 샘플 CSV | E8: 전원
A9: 8 | B9: 전기요금 계약종별 | C9: 대상 건물을 일반용/산업용 중 무엇으로 볼지 결정 → 단가 근거 | D9: 한전 요금표 | E9: 은미
A10: 9 | B10: 경제성 지표 정의 | C10: 회수기간 = 총공사비 ÷ 연 순절감액(단순) / 할인율 사용 여부 / 수명 기간 / 전동 장치 교체비 반영 여부 | D10: - | E10: 은미
A11: 10 | B11: 일정·판단 규칙 | C11: 스탠드업 시간·장소. 3일 저녁 Unity 기준(모델이 열리고 태양을 날짜·시각으로 움직일 수 있나), 5일 아침 반사광 기준(4일차까지 세 대안 경제성 표가 나왔나) | D11: - | E11: 전원

Sheet 5_1784운영규칙
A1: 1784 개폐 시각 (혜연 · 검증용 가정 시나리오 v1, 2026.10.06)
A2: 규칙: 태양 방위와 입면 정면의 방위차가 컷오프 이하이고 태양 고도 5° 이상이면 닫고, 아니면 연다. 공개 자료에 방위별 개폐 시각이 없어 태양 위치로 계산한 가정이다.
A3: 위치 37.35888°N 127.10518°E (1784, OSM) · 한국 표준시 UTC+9 · 컷오프는 표준·1784 자료가 아닌 팀 가정(±15° 민감도 예정)
A5: 대표일 | B5: 날짜 | C5: 컷오프(°) | D5: 입면 | E5: 입면방위각 | F5: 닫힘 시작 | G5: 닫힘 종료 | H5: 상태 | I5: 일출 | J5: 일몰 | K5: 정오 고도(°) | L5: 닫힘 시간(h)
A6: 춘분 | B6: 3/21 | C6: 30 | D6: 동 | E6: 90 | F6: 07:06 | G6: 09:34 | H6: 닫힘 | I6: 06:40 | J6: 18:40 | K6: 52.6 | L6: =IF(F6="","",ROUND(((LEFT(G6,2)*60+MID(G6,4,2))-(LEFT(F6,2)*60+MID(F6,4,2)))/60,1))
A7: 춘분 | B7: 3/21 | C7: 30 | D7: 남 | E7: 180 | F7: 11:23 | G7: 13:57 | H7: 닫힘 | I7: 06:40 | J7: 18:40 | K7: 52.6 | L7: =IF(F7="","",ROUND(((LEFT(G7,2)*60+MID(G7,4,2))-(LEFT(F7,2)*60+MID(F7,4,2)))/60,1))
A8: 춘분 | B8: 3/21 | C8: 30 | D8: 서 | E8: 270 | F8: 15:46 | G8: 18:15 | H8: 닫힘 | I8: 06:40 | J8: 18:40 | K8: 52.6 | L8: =IF(F8="","",ROUND(((LEFT(G8,2)*60+MID(G8,4,2))-(LEFT(F8,2)*60+MID(F8,4,2)))/60,1))
A9: 춘분 | B9: 3/21 | C9: 30 | D9: 북 | E9: 0 | H9: 종일 열림 | I9: 06:40 | J9: 18:40 | K9: 52.6 | L9: =IF(F9="","",ROUND(((LEFT(G9,2)*60+MID(G9,4,2))-(LEFT(F9,2)*60+MID(F9,4,2)))/60,1))
A10: 하지 | B10: 6/21 | C10: 60 | D10: 동 | E10: 90 | F10: 05:44 | G10: 11:59 | H10: 닫힘 | I10: 05:16 | J10: 19:51 | K10: 76.1 | L10: =IF(F10="","",ROUND(((LEFT(G10,2)*60+MID(G10,4,2))-(LEFT(F10,2)*60+MID(F10,4,2)))/60,1))
A11: 하지 | B11: 6/21 | C11: 60 | D11: 남 | E11: 180 | F11: 11:05 | G11: 14:02 | H11: 닫힘 | I11: 05:16 | J11: 19:51 | K11: 76.1 | L11: =IF(F11="","",ROUND(((LEFT(G11,2)*60+MID(G11,4,2))-(LEFT(F11,2)*60+MID(F11,4,2)))/60,1))
A12: 하지 | B12: 6/21 | C12: 60 | D12: 서 | E12: 270 | F12: 13:07 | G12: 19:22 | H12: 닫힘 | I12: 05:16 | J12: 19:51 | K12: 76.1 | L12: =IF(F12="","",ROUND(((LEFT(G12,2)*60+MID(G12,4,2))-(LEFT(F12,2)*60+MID(F12,4,2)))/60,1))
A13: 하지 | B13: 6/21 | C13: 60 | D13: 북 | E13: 0 | H13: 종일 열림 | I13: 05:16 | J13: 19:51 | K13: 76.1 | L13: =IF(F13="","",ROUND(((LEFT(G13,2)*60+MID(G13,4,2))-(LEFT(F13,2)*60+MID(F13,4,2)))/60,1))
A14: 추분 | B14: 9/23 | C14: 45 | D14: 동 | E14: 90 | F14: 06:49 | G14: 10:20 | H14: 닫힘 | I14: 06:23 | J14: 18:25 | K14: 52.9 | L14: =IF(F14="","",ROUND(((LEFT(G14,2)*60+MID(G14,4,2))-(LEFT(F14,2)*60+MID(F14,4,2)))/60,1))
A15: 추분 | B15: 9/23 | C15: 45 | D15: 남 | E15: 180 | F15: 10:20 | G15: 14:29 | H15: 닫힘 | I15: 06:23 | J15: 18:25 | K15: 52.9 | L15: =IF(F15="","",ROUND(((LEFT(G15,2)*60+MID(G15,4,2))-(LEFT(F15,2)*60+MID(F15,4,2)))/60,1))
A16: 추분 | B16: 9/23 | C16: 45 | D16: 서 | E16: 270 | F16: 14:29 | G16: 18:00 | H16: 닫힘 | I16: 06:23 | J16: 18:25 | K16: 52.9 | L16: =IF(F16="","",ROUND(((LEFT(G16,2)*60+MID(G16,4,2))-(LEFT(F16,2)*60+MID(F16,4,2)))/60,1))
A17: 추분 | B17: 9/23 | C17: 45 | D17: 북 | E17: 0 | H17: 종일 열림 | I17: 06:23 | J17: 18:25 | K17: 52.9 | L17: =IF(F17="","",ROUND(((LEFT(G17,2)*60+MID(G17,4,2))-(LEFT(F17,2)*60+MID(F17,4,2)))/60,1))
A18: 동지 | B18: 12/21 | C18: 30 | D18: 동 | E18: 90 | H18: 종일 열림 | I18: 07:47 | J18: 17:13 | K18: 29.2 | L18: =IF(F18="","",ROUND(((LEFT(G18,2)*60+MID(G18,4,2))-(LEFT(F18,2)*60+MID(F18,4,2)))/60,1))
A19: 동지 | B19: 12/21 | C19: 30 | D19: 남 | E19: 180 | F19: 10:29 | G19: 14:30 | H19: 닫힘 | I19: 07:47 | J19: 17:13 | K19: 29.2 | L19: =IF(F19="","",ROUND(((LEFT(G19,2)*60+MID(G19,4,2))-(LEFT(F19,2)*60+MID(F19,4,2)))/60,1))
A20: 동지 | B20: 12/21 | C20: 30 | D20: 서 | E20: 270 | H20: 종일 열림 | I20: 07:47 | J20: 17:13 | K20: 29.2 | L20: =IF(F20="","",ROUND(((LEFT(G20,2)*60+MID(G20,4,2))-(LEFT(F20,2)*60+MID(F20,4,2)))/60,1))
A21: 동지 | B21: 12/21 | C21: 30 | D21: 북 | E21: 0 | H21: 종일 열림 | I21: 07:47 | J21: 17:13 | K21: 29.2 | L21: =IF(F21="","",ROUND(((LEFT(G21,2)*60+MID(G21,4,2))-(LEFT(F21,2)*60+MID(F21,4,2)))/60,1))
A23: 근거 · 한계
A24: 삼우TV 영상 2:17 - 적정 창면적비 40~50%
A25: 삼우TV 영상 4:16 - 루버를 열면 창면적비 최대, 닫으면 창면적 축소 효과
A26: 삼우TV 영상 11:19 - 동서남북 4방향별 수직 루버 타공률이 다름
A27: 건축사신문, heyPOP 등 기사 - 방위별 개폐 수치 없음(혜연 확인)
A28: 컷오프·최소 고도는 팀 가정값. 흐린 날, 주변 건물 그림자, 조도는 반영하지 않음
A29: 입면 방위는 지도 기준이라 우정 모델과 대조 필요

Sheet 6_태양궤적(혜연)
A1: 대표일 | B1: 날짜 | C1: hoy | D1: 시각 | E1: 고도 | F1: 방위 | G1: 벡터X_동 | H1: 벡터Y_북 | I1: 벡터Z_위 | J1: 컷오프 | K1: 동면 | L1: 남면 | M1: 서면 | N1: 북면
A2: 춘분 | B2: 3/21 | C2: 1902.67 | D2: 06:40 | E2: 0 | F2: 90.2 | G2: 1 | H2: -0.0034 | I2: 0.0001 | J2: 30 | K2: 열림 | L2: 열림 | M2: 열림 | N2: 열림
A3: 춘분 | B3: 3/21 | C3: 1902.83 | D3: 06:50 | E3: 1.99 | F3: 91.71 | G3: 0.9989 | H3: -0.0299 | I3: 0.0348 | J3: 30 | K3: 열림 | L3: 열림 | M3: 열림 | N3: 열림
A4: 춘분 | B4: 3/21 | C4: 1903 | D4: 07:00 | E4: 3.98 | F4: 93.23 | G4: 0.996 | H4: -0.0563 | I4: 0.0694 | J4: 30 | K4: 열림 | L4: 열림 | M4: 열림 | N4: 열림
A5: 춘분 | B5: 3/21 | C5: 1903.17 | D5: 07:10 | E5: 5.97 | F5: 94.76 | G5: 0.9912 | H5: -0.0825 | I5: 0.1039 | J5: 30 | K5: 닫힘 | L5: 열림 | M5: 열림 | N5: 열림
A6: 춘분 | B6: 3/21 | C6: 1903.33 | D6: 07:20 | E6: 7.95 | F6: 96.3 | G6: 0.9844 | H6: -0.1087 | I6: 0.1382 | J6: 30 | K6: 닫힘 | L6: 열림 | M6: 열림 | N6: 열림
A7: 춘분 | B7: 3/21 | C7: 1903.5 | D7: 07:30 | E7: 9.92 | F7: 97.85 | G7: 0.9758 | H7: -0.1346 | I7: 0.1723 | J7: 30 | K7: 닫힘 | L7: 열림 | M7: 열림 | N7: 열림
A8: 춘분 | B8: 3/21 | C8: 1903.67 | D8: 07:40 | E8: 11.89 | F8: 99.43 | G8: 0.9653 | H8: -0.1603 | I8: 0.206 | J8: 30 | K8: 닫힘 | L8: 열림 | M8: 열림 | N8: 열림
A9: 춘분 | B9: 3/21 | C9: 1903.83 | D9: 07:50 | E9: 13.84 | F9: 101.02 | G9: 0.953 | H9: -0.1856 | I9: 0.2393 | J9: 30 | K9: 닫힘 | L9: 열림 | M9: 열림 | N9: 열림
A10: 춘분 | B10: 3/21 | C10: 1904 | D10: 08:00 | E10: 15.79 | F10: 102.64 | G10: 0.9389 | H10: -0.2106 | I10: 0.2721 | J10: 30 | K10: 닫힘 | L10: 열림 | M10: 열림 | N10: 열림
A11: 춘분 | B11: 3/21 | C11: 1904.17 | D11: 08:10 | E11: 17.73 | F11: 104.3 | G11: 0.923 | H11: -0.2353 | I11: 0.3045 | J11: 30 | K11: 닫힘 | L11: 열림 | M11: 열림 | N11: 열림
A12: 춘분 | B12: 3/21 | C12: 1904.33 | D12: 08:20 | E12: 19.65 | F12: 105.99 | G12: 0.9054 | H12: -0.2594 | I12: 0.3362 | J12: 30 | K12: 닫힘 | L12: 열림 | M12: 열림 | N12: 열림
A13: 춘분 | B13: 3/21 | C13: 1904.5 | D13: 08:30 | E13: 21.55 | F13: 107.72 | G13: 0.886 | H13: -0.2831 | I13: 0.3673 | J13: 30 | K13: 닫힘 | L13: 열림 | M13: 열림 | N13: 열림
... A290: 동지 | B290: 12/21 | C290: 8513.17 | D290: 17:10 | E290: 0.39 | F290: 239.65 | G290: -0.8629 | H290: -0.5053 | I290: 0.0068 | J290: 30 | K290: 열림 | L290: 열림 | M290: 열림 | N290: 열림

Sheet 7_공사비
A1: ① 공사비 산출 — 얼마 드나
A2: 모든 단가는 2_단가조사 기준값 × 단가 배율. 물량은 1_입력값(우정 Revit 일람표). 루버는 동·남·서면에만 설치(북면 제외). 시공 전(일반 통유리)은 공사비 0.
A3: 항목 | B3: 산출 근거 | C3: 내부 반응형 | D3: 외부 고정 | E3: 외부 반응형
A4: 루버 자재 | B4: 루버 면적 × ㎡당 단가 (내부는 내부 루버 단가) | C4: ='1_입력값'!$D$11*'2_단가조사'!$F$17*'1_입력값'!$D$31 | D4: ='1_입력값'!$D$8*'2_단가조사'!$F$2*'1_입력값'!$D$31 | E4: ='1_입력값'!$D$9*'2_단가조사'!$F$2*'1_입력값'!$D$31
A5: 지지 프레임·부속 | B5: 루버 면적 × ㎡당 단가 (내부는 자재 단가에 포함 가정) | C5: =0 | D5: ='1_입력값'!$D$8*'2_단가조사'!$F$3*'1_입력값'!$D$31 | E5: ='1_입력값'!$D$9*'2_단가조사'!$F$3*'1_입력값'!$D$31
A6: 구동장치·센서·제어 | B6: 구동 유닛 수 × 단가 + 제어 시스템 (반응형만) | C6: =('1_입력값'!$D$45*'2_단가조사'!$F$4+'2_단가조사'!$F$5)*'1_입력값'!$D$31 | D6: =0 | E6: =('1_입력값'!$D$10*'2_단가조사'!$F$4+'2_단가조사'!$F$5)*'1_입력값'!$D$31
A7: 소프트웨어(앱) 개발 | B7: 수동 작동 앱 개발비 1회 (반응형만) | C7: ='2_단가조사'!$F$19*'1_입력값'!$D$31 | D7: =0 | E7: ='2_단가조사'!$F$19*'1_입력값'!$D$31
A8: 보호 유리 | B8: 창 면적 × 보호 유리 단가 × 포함 스위치 (외부만) | C8: =0 | D8: ='1_입력값'!$D$48*'1_입력값'!$D$6*'2_단가조사'!$F$21*'1_입력값'!$D$31 | E8: ='1_입력값'!$D$47*'1_입력값'!$D$6*'2_단가조사'!$F$21*'1_입력값'!$D$31
A9: 설치 공사 | B9: 설치 면적 × 시공 단가 | C9: ='1_입력값'!$D$11*'2_단가조사'!$F$18*'1_입력값'!$D$31 | D9: ='1_입력값'!$D$8*'2_단가조사'!$F$6*'1_입력값'!$D$31 | E9: ='1_입력값'!$D$9*'2_단가조사'!$F$6*'1_입력값'!$D$31
A10: 가설·장비 | B10: 내부: 고소작업 일수 × 일대 / 외부: 일수 × (곤돌라 + 고소작업차) | C10: ='1_입력값'!$D$46*'2_단가조사'!$F$8*'1_입력값'!$D$31 | D10: ='1_입력값'!$D$12*('2_단가조사'!$F$7+'2_단가조사'!$F$8)*'1_입력값'!$D$31 | E10: ='1_입력값'!$D$12*('2_단가조사'!$F$7+'2_단가조사'!$F$8)*'1_입력값'!$D$31
A11: 직접 공사비 | B11: 위 항목 합계 | C11: =SUM(C4:C10) | D11: =SUM(D4:D10) | E11: =SUM(E4:E10)
A12: 설계·감리비 | B12: 직접 공사비 × 비율 | C12: =C11*'1_입력값'!$D$13/100 | D12: =D11*'1_입력값'!$D$13/100 | E12: =E11*'1_입력값'!$D$13/100
A13: 예비비 | B13: 직접 공사비 × 비율 | C13: =C11*'1_입력값'!$D$14/100 | D13: =D11*'1_입력값'!$D$14/100 | E13: =E11*'1_입력값'!$D$14/100
A14: 총 공사비 | B14: 직접 공사비 + 설계·감리 + 예비비 | C14: =C11+C12+C13 | D14: =D11+D12+D13 | E14: =E11+E12+E13

Sheet 8_시공전후
A1: ② 시공 전 · 후 비교 (연간) — 무엇이 달라지나
A2: 냉방 = 일사량 × 창 면적 × 냉방 부하/일사 (1.13, 팀 EnergyPlus) ÷ 냉방 COP (3.5). 일사량은 팀 Radiance 1784 1~28층 평균. 루버를 다는 동·남·서면만 계산합니다(북면은 모든 대안에서 같아 비교에서 상쇄). 난방 증가분은 13_탄소·계절효과에서 가져와 에너지 비용에 넣습니다.
A3: 항목 | B3: 산출 근거 | C3: 시공 전 (일반 통유리) | D3: 내부 반응형 | E3: 외부 고정 | F3: 외부 반응형
A4: 적용 차양계수 | B4: 차양계수 표(기준) 또는 1(미적용) | C4: =IF('1_입력값'!$D$44=1,'3_차폐·냉방환산'!C7,1) | D4: =IF('1_입력값'!$D$44=1,'3_차폐·냉방환산'!C8,1) | E4: =IF('1_입력값'!$D$44=1,'3_차폐·냉방환산'!C9,1) | F4: =IF('1_입력값'!$D$44=1,'3_차폐·냉방환산'!C10,1)
A5: 입사 일사량 (kWh/㎡·년) | B5: 혜연 | C5: ='1_입력값'!$D$36 | D5: ='1_입력값'!$D$37 | E5: ='1_입력값'!$D$38 | F5: ='1_입력값'!$D$39
A6: 냉방 부하 (kWh/년) | B6: 일사량 × 창면적 × 냉방 부하/일사 (1.13) × 차양계수 | C6: =C5*'1_입력값'!$D$6*'1_입력값'!$D$21*C4 | D6: =D5*'1_입력값'!$D$6*'1_입력값'!$D$21*D4 | E6: =E5*'1_입력값'!$D$6*'1_입력값'!$D$21*E4 | F6: =F5*'1_입력값'!$D$6*'1_입력값'!$D$21*F4
A7: 냉방 전력 (kWh/년) | B7: 냉방 부하 ÷ 냉방 COP (3.5) | C7: =C6/'1_입력값'!$D$20 | D7: =D6/'1_입력값'!$D$20 | E7: =E6/'1_입력값'!$D$20 | F7: =F6/'1_입력값'!$D$20
A8: 냉방 전기요금 (원/년) | B8: 냉방 전력 × 전기요금 | C8: =C7*'1_입력값'!$D$15*'1_입력값'!$D$32 | D8: =D7*'1_입력값'!$D$15*'1_입력값'!$D$32 | E8: =E7*'1_입력값'!$D$15*'1_입력값'!$D$32 | F8: =F7*'1_입력값'!$D$15*'1_입력값'!$D$32
A9: 조명 전력 (kWh/년) | B9: 서우 | C9: ='1_입력값'!$D$40 | D9: ='1_입력값'!$D$41 | E9: ='1_입력값'!$D$42 | F9: ='1_입력값'!$D$43
A10: 조명 전기요금 (원/년) | B10: 조명 전력 × 전기요금 | C10: =C9*'1_입력값'!$D$15*'1_입력값'!$D$32 | D10: =D9*'1_입력값'!$D$15*'1_입력값'!$D$32 | E10: =E9*'1_입력값'!$D$15*'1_입력값'!$D$32 | F10: =F9*'1_입력값'!$D$15*'1_입력값'!$D$32
A11: 연간 에너지 비용 (원) | B11: 냉방 + 조명 + 난방 증가분 (13_탄소 ③) | C11: =C8+C10+'13_탄소·계절효과'!B25*1000*'1_입력값'!$D$15*'1_입력값'!$D$32 | D11: =D8+D10+'13_탄소·계절효과'!C25*1000*'1_입력값'!$D$15*'1_입력값'!$D$32 | E11: =E8+E10+'13_탄소·계절효과'!D25*1000*'1_입력값'!$D$15*'1_입력값'!$D$32 | F11: =F8+F10+'13_탄소·계절효과'!E25*1000*'1_입력값'!$D$15*'1_입력값'!$D$32
A12: 연간 에너지 절감액 (시공 전 대비) | B12: 시공 전 비용 − 대안 비용 | C12: =$C$11-C11 | D12: =$C$11-D11 | E12: =$C$11-E11 | F12: =$C$11-F11
A13: 추가 유지관리비 (원/년) | B13: 루버 시스템비 (날·프레임·구동·설치) × 유지비율 + 보호 유리 × 1% + 구동장치 교체 (보호 10년 / 노출 5년마다, 수명 안 횟수 ÷ 수명) + 앱 연 운영비 | C13: 0 | D13: =('7_공사비'!C4+'7_공사비'!C5+'7_공사비'!C6+'7_공사비'!C9)*'1_입력값'!$D$34/100*'1_입력값'!$D$33+'7_공사비'!C8*'1_입력값'!$D$64/100*'1_입력값'!$D$33+INT(('1_입력값'!$D$17-1)/'1_입력값'!$D$35)*'1_입력값'!$D$45*'2_단가조사'!$F$4*'1_입력값'!$D$31/'1_입력값'!$D$17+'2_단가조사'!$F$20*'1_입력값'!$D$33 | E13: =('7_공사비'!D4+'7_공사비'!D5+'7_공사비'!D6+'7_공사비'!D9)*'1_입력값'!$D$18/100*'1_입력값'!$D$33+'7_공사비'!D8*'1_입력값'!$D$64/100*'1_입력값'!$D$33 | F13: =('7_공사비'!E4+'7_공사비'!E5+'7_공사비'!E6+'7_공사비'!E9)*'1_입력값'!$D$34/100*'1_입력값'!$D$33+'7_공사비'!E8*'1_입력값'!$D$64/100*'1_입력값'!$D$33+INT(('1_입력값'!$D$17-1)/IF('1_입력값'!$D$47=1,'1_입력값'!$D$35,'1_입력값'!$D$63))*'1_입력값'!$D$10*'2_단가조사'!$F$4*'1_입력값'!$D$31/'1_입력값'!$D$17+'2_단가조사'!$F$20*'1_입력값'!$D$33
A14: 연간 순절감액 (원) | B14: 에너지 절감 − 추가 유지관리비 | C14: =C12-C13 | D14: =D12-D13 | E14: =E12-E13 | F14: =F12-F13
A15: 주변 아파트 반사광 도달 시간 | B15: 확장 시 (5일차 판단) | C15: - | D15: - | E15: - | F15: -

Sheet 9_발주처이익
A1: ③ 발주처 이익 — 그래서 얼마 남나
A2: 시공 전(일반 통유리) 대비 값입니다. 분석 기간은 루버 수명. 전기요금 인상은 10_누적·민감도의 누적 곡선에 반영하고, 이 표는 현재 요금 기준 단순 계산입니다.
A3: 지표 | B3: 산출 근거 | C3: 내부 반응형 | D3: 외부 고정 | E3: 외부 반응형
A4: 총 공사비 (원) | B4: 7_공사비 | C4: ='7_공사비'!C14 | D4: ='7_공사비'!D14 | E4: ='7_공사비'!E14
A5: 연간 순절감액 (원) | B5: 8_시공전후 | C5: ='8_시공전후'!D14 | D5: ='8_시공전후'!E14 | E5: ='8_시공전후'!F14
A6: 회수 기간 (년) | B6: 총 공사비 ÷ 연 순절감액 | C6: =IF(C5<=0,"회수 불가",C4/C5) | D6: =IF(D5<=0,"회수 불가",D4/D5) | E6: =IF(E5<=0,"회수 불가",E4/E5)
A7: 분석 기간 (년) | B7: 루버 수명 | C7: ='1_입력값'!D17 | D7: ='1_입력값'!D17 | E7: ='1_입력값'!D17
A8: 수명 기간 누적 순이익 (원) | B8: 순절감액 × 기간 − 공사비 | C8: =C5*C7-C4 | D8: =D5*D7-D4 | E8: =E5*E7-E4
A9: 투자 수익률 (연, %) | B9: 연 순절감액 ÷ 총 공사비 × 100 | C9: =C5/C4*100 | D9: =D5/D4*100 | E9: =E5/E4*100
A10: 손익분기 연도 (전기요금 인상 반영) | B10: 누적 비용이 시공 전보다 낮아지는 첫 해 (10_누적·민감도, 최대 60년, 인센티브 스위치 반영) | C10: =IF(COUNT('10_누적·민감도'!F4:F64)=0,"60년 초과",MIN('10_누적·민감도'!F4:F64)) | D10: =IF(COUNT('10_누적·민감도'!G4:G64)=0,"60년 초과",MIN('10_누적·민감도'!G4:G64)) | E10: =IF(COUNT('10_누적·민감도'!H4:H64)=0,"60년 초과",MIN('10_누적·민감도'!H4:H64))
A11: 인센티브 일시 혜택 (원) | B11: 11_인센티브 (스위치 켠 경우만, 공사비에서 차감하는 효과) | C11: ='11_인센티브'!B24 | D11: ='11_인센티브'!C24 | E11: ='11_인센티브'!D24
A12: 인센티브 연 혜택 (원/년) | B12: 재산세 감면 + 이자지원 (감면 기간 동안) | C12: ='11_인센티브'!B25+'11_인센티브'!B26 | D12: ='11_인센티브'!C25+'11_인센티브'!C26 | E12: ='11_인센티브'!D25+'11_인센티브'!D26
A13: 숫자로 안 잡히는 이익 | B13: 외관 변화(내부·외부 루버 연출), 실내 쾌적성, 내부 루버 연출 유지(반응형), 주변 민원·분쟁 위험 감소(확장 시), 이미 검증된 방식(1784)
A14: 주의 | B14: 구동장치 교체비 반영: 보호 유리 안 · 실내 10년, 바깥 노출 5년마다 구동 유닛 전체 교체 (8_시공전후 13행). 에너지 절감에 난방 증가분 포함.

Sheet 10_누적·민감도
A1: 누적 비용 (공사비 + 운영비 누적) — 건우에게 그래프 디자인용 데이터
A2: 전기요금 연 인상률 반영. 엑셀에서 A~E열을 선택 → 삽입 → 꺾은선 차트로 바로 그릴 수 있습니다. 선이 교차하는 연도가 회수 연도입니다.
A3: 연도 | B3: 시공 전 (통유리) | C3: 내부 반응형 | D3: 외부 고정 | E3: 외부 반응형 | F3: 손익분기 연도(내부) | G3: 손익분기 연도(외부 고정) | H3: 손익분기 연도(외부 반응)
A4: 0 | B4: ='8_시공전후'!C11*IF(('1_입력값'!$D$16/100)=0,A4,((1+('1_입력값'!$D$16/100))^A4-1)/('1_입력값'!$D$16/100)) | C4: ='7_공사비'!C14+'8_시공전후'!D11*IF(('1_입력값'!$D$16/100)=0,A4,((1+('1_입력값'!$D$16/100))^A4-1)/('1_입력값'!$D$16/100))+'8_시공전후'!D13*A4-('11_인센티브'!B$24+'11_인센티브'!B$25*MIN(A4,'11_인센티브'!$B$12)+'11_인센티브'!B$26*MIN(A4,'11_인센티브'!$B$15)) | D4: ='7_공사비'!D14+'8_시공전후'!E11*IF(('1_입력값'!$D$16/100)=0,A4,((1+('1_입력값'!$D$16/100))^A4-1)/('1_입력값'!$D$16/100))+'8_시공전후'!E13*A4-('11_인센티브'!C$24+'11_인센티브'!C$25*MIN(A4,'11_인센티브'!$B$12)+'11_인센티브'!C$26*MIN(A4,'11_인센티브'!$B$15)) | E4: ='7_공사비'!E14+'8_시공전후'!F11*IF(('1_입력값'!$D$16/100)=0,A4,((1+('1_입력값'!$D$16/100))^A4-1)/('1_입력값'!$D$16/100))+'8_시공전후'!F13*A4-('11_인센티브'!D$24+'11_인센티브'!D$25*MIN(A4,'11_인센티브'!$B$12)+'11_인센티브'!D$26*MIN(A4,'11_인센티브'!$B$15)) | F4: =IF(C4<=B4,A4,"") | G4: =IF(D4<=B4,A4,"") | H4: =IF(E4<=B4,A4,"")
A5: 1 | B5: ='8_시공전후'!C11*IF(('1_입력값'!$D$16/100)=0,A5,((1+('1_입력값'!$D$16/100))^A5-1)/('1_입력값'!$D$16/100)) | C5: ='7_공사비'!C14+'8_시공전후'!D11*IF(('1_입력값'!$D$16/100)=0,A5,((1+('1_입력값'!$D$16/100))^A5-1)/('1_입력값'!$D$16/100))+'8_시공전후'!D13*A5-('11_인센티브'!B$24+'11_인센티브'!B$25*MIN(A5,'11_인센티브'!$B$12)+'11_인센티브'!B$26*MIN(A5,'11_인센티브'!$B$15)) | D5: ='7_공사비'!D14+'8_시공전후'!E11*IF(('1_입력값'!$D$16/100)=0,A5,((1+('1_입력값'!$D$16/100))^A5-1)/('1_입력값'!$D$16/100))+'8_시공전후'!E13*A5-('11_인센티브'!C$24+'11_인센티브'!C$25*MIN(A5,'11_인센티브'!$B$12)+'11_인센티브'!C$26*MIN(A5,'11_인센티브'!$B$15)) | E5: ='7_공사비'!E14+'8_시공전후'!F11*IF(('1_입력값'!$D$16/100)=0,A5,((1+('1_입력값'!$D$16/100))^A5-1)/('1_입력값'!$D$16/100))+'8_시공전후'!F13*A5-('11_인센티브'!D$24+'11_인센티브'!D$25*MIN(A5,'11_인센티브'!$B$12)+'11_인센티브'!D$26*MIN(A5,'11_인센티브'!$B$15)) | F5: =IF(C5<=B5,A5,"") | G5: =IF(D5<=B5,A5,"") | H5: =IF(E5<=B5,A5,"")
A6: 2 | B6: ='8_시공전후'!C11*IF(('1_입력값'!$D$16/100)=0,A6,((1+('1_입력값'!$D$16/100))^A6-1)/('1_입력값'!$D$16/100)) | C6: ='7_공사비'!C14+'8_시공전후'!D11*IF(('1_입력값'!$D$16/100)=0,A6,((1+('1_입력값'!$D$16/100))^A6-1)/('1_입력값'!$D$16/100))+'8_시공전후'!D13*A6-('11_인센티브'!B$24+'11_인센티브'!B$25*MIN(A6,'11_인센티브'!$B$12)+'11_인센티브'!B$26*MIN(A6,'11_인센티브'!$B$15)) | D6: ='7_공사비'!D14+'8_시공전후'!E11*IF(('1_입력값'!$D$16/100)=0,A6,((1+('1_입력값'!$D$16/100))^A6-1)/('1_입력값'!$D$16/100))+'8_시공전후'!E13*A6-('11_인센티브'!C$24+'11_인센티브'!C$25*MIN(A6,'11_인센티브'!$B$12)+'11_인센티브'!C$26*MIN(A6,'11_인센티브'!$B$15)) | E6: ='7_공사비'!E14+'8_시공전후'!F11*IF(('1_입력값'!$D$16/100)=0,A6,((1+('1_입력값'!$D$16/100))^A6-1)/('1_입력값'!$D$16/100))+'8_시공전후'!F13*A6-('11_인센티브'!D$24+'11_인센티브'!D$25*MIN(A6,'11_인센티브'!$B$12)+'11_인센티브'!D$26*MIN(A6,'11_인센티브'!$B$15)) | F6: =IF(C6<=B6,A6,"") | G6: =IF(D6<=B6,A6,"") | H6: =IF(E6<=B6,A6,"")
A7: 3 | B7: ='8_시공전후'!C11*IF(('1_입력값'!$D$16/100)=0,A7,((1+('1_입력값'!$D$16/100))^A7-1)/('1_입력값'!$D$16/100)) | C7: ='7_공사비'!C14+'8_시공전후'!D11*IF(('1_입력값'!$D$16/100)=0,A7,((1+('1_입력값'!$D$16/100))^A7-1)/('1_입력값'!$D$16/100))+'8_시공전후'!D13*A7-('11_인센티브'!B$24+'11_인센티브'!B$25*MIN(A7,'11_인센티브'!$B$12)+'11_인센티브'!B$26*MIN(A7,'11_인센티브'!$B$15)) | D7: ='7_공사비'!D14+'8_시공전후'!E11*IF(('1_입력값'!$D$16/100)=0,A7,((1+('1_입력값'!$D$16/100))^A7-1)/('1_입력값'!$D$16/100))+'8_시공전후'!E13*A7-('11_인센티브'!C$24+'11_인센티브'!C$25*MIN(A7,'11_인센티브'!$B$12)+'11_인센티브'!C$26*MIN(A7,'11_인센티브'!$B$15)) | E7: ='7_공사비'!E14+'8_시공전후'!F11*IF(('1_입력값'!$D$16/100)=0,A7,((1+('1_입력값'!$D$16/100))^A7-1)/('1_입력값'!$D$16/100))+'8_시공전후'!F13*A7-('11_인센티브'!D$24+'11_인센티브'!D$25*MIN(A7,'11_인센티브'!$B$12)+'11_인센티브'!D$26*MIN(A7,'11_인센티브'!$B$15)) | F7: =IF(C7<=B7,A7,"") | G7: =IF(D7<=B7,A7,"") | H7: =IF(E7<=B7,A7,"")
A8: 4 | B8: ='8_시공전후'!C11*IF(('1_입력값'!$D$16/100)=0,A8,((1+('1_입력값'!$D$16/100))^A8-1)/('1_입력값'!$D$16/100)) | C8: ='7_공사비'!C14+'8_시공전후'!D11*IF(('1_입력값'!$D$16/100)=0,A8,((1+('1_입력값'!$D$16/100))^A8-1)/('1_입력값'!$D$16/100))+'8_시공전후'!D13*A8-('11_인센티브'!B$24+'11_인센티브'!B$25*MIN(A8,'11_인센티브'!$B$12)+'11_인센티브'!B$26*MIN(A8,'11_인센티브'!$B$15)) | D8: ='7_공사비'!D14+'8_시공전후'!E11*IF(('1_입력값'!$D$16/100)=0,A8,((1+('1_입력값'!$D$16/100))^A8-1)/('1_입력값'!$D$16/100))+'8_시공전후'!E13*A8-('11_인센티브'!C$24+'11_인센티브'!C$25*MIN(A8,'11_인센티브'!$B$12)+'11_인센티브'!C$26*MIN(A8,'11_인센티브'!$B$15)) | E8: ='7_공사비'!E14+'8_시공전후'!F11*IF(('1_입력값'!$D$16/100)=0,A8,((1+('1_입력값'!$D$16/100))^A8-1)/('1_입력값'!$D$16/100))+'8_시공전후'!F13*A8-('11_인센티브'!D$24+'11_인센티브'!D$25*MIN(A8,'11_인센티브'!$B$12)+'11_인센티브'!D$26*MIN(A8,'11_인센티브'!$B$15)) | F8: =IF(C8<=B8,A8,"") | G8: =IF(D8<=B8,A8,"") | H8: =IF(E8<=B8,A8,"")
A9: 5 | B9: ='8_시공전후'!C11*IF(('1_입력값'!$D$16/100)=0,A9,((1+('1_입력값'!$D$16/100))^A9-1)/('1_입력값'!$D$16/100)) | C9: ='7_공사비'!C14+'8_시공전후'!D11*IF(('1_입력값'!$D$16/100)=0,A9,((1+('1_입력값'!$D$16/100))^A9-1)/('1_입력값'!$D$16/100))+'8_시공전후'!D13*A9-('11_인센티브'!B$24+'11_인센티브'!B$25*MIN(A9,'11_인센티브'!$B$12)+'11_인센티브'!B$26*MIN(A9,'11_인센티브'!$B$15)) | D9: ='7_공사비'!D14+'8_시공전후'!E11*IF(('1_입력값'!$D$16/100)=0,A9,((1+('1_입력값'!$D$16/100))^A9-1)/('1_입력값'!$D$16/100))+'8_시공전후'!E13*A9-('11_인센티브'!C$24+'11_인센티브'!C$25*MIN(A9,'11_인센티브'!$B$12)+'11_인센티브'!C$26*MIN(A9,'11_인센티브'!$B$15)) | E9: ='7_공사비'!E14+'8_시공전후'!F11*IF(('1_입력값'!$D$16/100)=0,A9,((1+('1_입력값'!$D$16/100))^A9-1)/('1_입력값'!$D$16/100))+'8_시공전후'!F13*A9-('11_인센티브'!D$24+'11_인센티브'!D$25*MIN(A9,'11_인센티브'!$B$12)+'11_인센티브'!D$26*MIN(A9,'11_인센티브'!$B$15)) | F9: =IF(C9<=B9,A9,"") | G9: =IF(D9<=B9,A9,"") | H9: =IF(E9<=B9,A9,"")
A10: 6 | B10: ='8_시공전후'!C11*IF(('1_입력값'!$D$16/100)=0,A10,((1+('1_입력값'!$D$16/100))^A10-1)/('1_입력값'!$D$16/100)) | C10: ='7_공사비'!C14+'8_시공전후'!D11*IF(('1_입력값'!$D$16/100)=0,A10,((1+('1_입력값'!$D$16/100))^A10-1)/('1_입력값'!$D$16/100))+'8_시공전후'!D13*A10-('11_인센티브'!B$24+'11_인센티브'!B$25*MIN(A10,'11_인센티브'!$B$12)+'11_인센티브'!B$26*MIN(A10,'11_인센티브'!$B$15)) | D10: ='7_공사비'!D14+'8_시공전후'!E11*IF(('1_입력값'!$D$16/100)=0,A10,((1+('1_입력값'!$D$16/100))^A10-1)/('1_입력값'!$D$16/100))+'8_시공전후'!E13*A10-('11_인센티브'!C$24+'11_인센티브'!C$25*MIN(A10,'11_인센티브'!$B$12)+'11_인센티브'!C$26*MIN(A10,'11_인센티브'!$B$15)) | E10: ='7_공사비'!E14+'8_시공전후'!F11*IF(('1_입력값'!$D$16/100)=0,A10,((1+('1_입력값'!$D$16/100))^A10-1)/('1_입력값'!$D$16/100))+'8_시공전후'!F13*A10-('11_인센티브'!D$24+'11_인센티브'!D$25*MIN(A10,'11_인센티브'!$B$12)+'11_인센티브'!D$26*MIN(A10,'11_인센티브'!$B$15)) | F10: =IF(C10<=B10,A10,"") | G10: =IF(D10<=B10,A10,"") | H10: =IF(E10<=B10,A10,"")
A11: 7 | B11: ='8_시공전후'!C11*IF(('1_입력값'!$D$16/100)=0,A11,((1+('1_입력값'!$D$16/100))^A11-1)/('1_입력값'!$D$16/100)) | C11: ='7_공사비'!C14+'8_시공전후'!D11*IF(('1_입력값'!$D$16/100)=0,A11,((1+('1_입력값'!$D$16/100))^A11-1)/('1_입력값'!$D$16/100))+'8_시공전후'!D13*A11-('11_인센티브'!B$24+'11_인센티브'!B$25*MIN(A11,'11_인센티브'!$B$12)+'11_인센티브'!B$26*MIN(A11,'11_인센티브'!$B$15)) | D11: ='7_공사비'!D14+'8_시공전후'!E11*IF(('1_입력값'!$D$16/100)=0,A11,((1+('1_입력값'!$D$16/100))^A11-1)/('1_입력값'!$D$16/100))+'8_시공전후'!E13*A11-('11_인센티브'!C$24+'11_인센티브'!C$25*MIN(A11,'11_인센티브'!$B$12)+'11_인센티브'!C$26*MIN(A11,'11_인센티브'!$B$15)) | E11: ='7_공사비'!E14+'8_시공전후'!F11*IF(('1_입력값'!$D$16/100)=0,A11,((1+('1_입력값'!$D$16/100))^A11-1)/('1_입력값'!$D$16/100))+'8_시공전후'!F13*A11-('11_인센티브'!D$24+'11_인센티브'!D$25*MIN(A11,'11_인센티브'!$B$12)+'11_인센티브'!D$26*MIN(A11,'11_인센티브'!$B$15)) | F11: =IF(C11<=B11,A11,"") | G11: =IF(D11<=B11,A11,"") | H11: =IF(E11<=B11,A11,"")
A12: 8 | B12: ='8_시공전후'!C11*IF(('1_입력값'!$D$16/100)=0,A12,((1+('1_입력값'!$D$16/100))^A12-1)/('1_입력값'!$D$16/100)) | C12: ='7_공사비'!C14+'8_시공전후'!D11*IF(('1_입력값'!$D$16/100)=0,A12,((1+('1_입력값'!$D$16/100))^A12-1)/('1_입력값'!$D$16/100))+'8_시공전후'!D13*A12-('11_인센티브'!B$24+'11_인센티브'!B$25*MIN(A12,'11_인센티브'!$B$12)+'11_인센티브'!B$26*MIN(A12,'11_인센티브'!$B$15)) | D12: ='7_공사비'!D14+'8_시공전후'!E11*IF(('1_입력값'!$D$16/100)=0,A12,((1+('1_입력값'!$D$16/100))^A12-1)/('1_입력값'!$D$16/100))+'8_시공전후'!E13*A12-('11_인센티브'!C$24+'11_인센티브'!C$25*MIN(A12,'11_인센티브'!$B$12)+'11_인센티브'!C$26*MIN(A12,'11_인센티브'!$B$15)) | E12: ='7_공사비'!E14+'8_시공전후'!F11*IF(('1_입력값'!$D$16/100)=0,A12,((1+('1_입력값'!$D$16/100))^A12-1)/('1_입력값'!$D$16/100))+'8_시공전후'!F13*A12-('11_인센티브'!D$24+'11_인센티브'!D$25*MIN(A12,'11_인센티브'!$B$12)+'11_인센티브'!D$26*MIN(A12,'11_인센티브'!$B$15)) | F12: =IF(C12<=B12,A12,"") | G12: =IF(D12<=B12,A12,"") | H12: =IF(E12<=B12,A12,"")
A13: 9 | B13: ='8_시공전후'!C11*IF(('1_입력값'!$D$16/100)=0,A13,((1+('1_입력값'!$D$16/100))^A13-1)/('1_입력값'!$D$16/100)) | C13: ='7_공사비'!C14+'8_시공전후'!D11*IF(('1_입력값'!$D$16/100)=0,A13,((1+('1_입력값'!$D$16/100))^A13-1)/('1_입력값'!$D$16/100))+'8_시공전후'!D13*A13-('11_인센티브'!B$24+'11_인센티브'!B$25*MIN(A13,'11_인센티브'!$B$12)+'11_인센티브'!B$26*MIN(A13,'11_인센티브'!$B$15)) | D13: ='7_공사비'!D14+'8_시공전후'!E11*IF(('1_입력값'!$D$16/100)=0,A13,((1+('1_입력값'!$D$16/100))^A13-1)/('1_입력값'!$D$16/100))+'8_시공전후'!E13*A13-('11_인센티브'!C$24+'11_인센티브'!C$25*MIN(A13,'11_인센티브'!$B$12)+'11_인센티브'!C$26*MIN(A13,'11_인센티브'!$B$15)) | E13: ='7_공사비'!E14+'8_시공전후'!F11*IF(('1_입력값'!$D$16/100)=0,A13,((1+('1_입력값'!$D$16/100))^A13-1)/('1_입력값'!$D$16/100))+'8_시공전후'!F13*A13-('11_인센티브'!D$24+'11_인센티브'!D$25*MIN(A13,'11_인센티브'!$B$12)+'11_인센티브'!D$26*MIN(A13,'11_인센티브'!$B$15)) | F13: =IF(C13<=B13,A13,"") | G13: =IF(D13<=B13,A13,"") | H13: =IF(E13<=B13,A13,"")
A14: 10 | B14: ='8_시공전후'!C11*IF(('1_입력값'!$D$16/100)=0,A14,((1+('1_입력값'!$D$16/100))^A14-1)/('1_입력값'!$D$16/100)) | C14: ='7_공사비'!C14+'8_시공전후'!D11*IF(('1_입력값'!$D$16/100)=0,A14,((1+('1_입력값'!$D$16/100))^A14-1)/('1_입력값'!$D$16/100))+'8_시공전후'!D13*A14-('11_인센티브'!B$24+'11_인센티브'!B$25*MIN(A14,'11_인센티브'!$B$12)+'11_인센티브'!B$26*MIN(A14,'11_인센티브'!$B$15)) | D14: ='7_공사비'!D14+'8_시공전후'!E11*IF(('1_입력값'!$D$16/100)=0,A14,((1+('1_입력값'!$D$16/100))^A14-1)/('1_입력값'!$D$16/100))+'8_시공전후'!E13*A14-('11_인센티브'!C$24+'11_인센티브'!C$25*MIN(A14,'11_인센티브'!$B$12)+'11_인센티브'!C$26*MIN(A14,'11_인센티브'!$B$15)) | E14: ='7_공사비'!E14+'8_시공전후'!F11*IF(('1_입력값'!$D$16/100)=0,A14,((1+('1_입력값'!$D$16/100))^A14-1)/('1_입력값'!$D$16/100))+'8_시공전후'!F13*A14-('11_인센티브'!D$24+'11_인센티브'!D$25*MIN(A14,'11_인센티브'!$B$12)+'11_인센티브'!D$26*MIN(A14,'11_인센티브'!$B$15)) | F14: =IF(C14<=B14,A14,"") | G14: =IF(D14<=B14,A14,"") | H14: =IF(E14<=B14,A14,"")
A15: 11 | B15: ='8_시공전후'!C11*IF(('1_입력값'!$D$16/100)=0,A15,((1+('1_입력값'!$D$16/100))^A15-1)/('1_입력값'!$D$16/100)) | C15: ='7_공사비'!C14+'8_시공전후'!D11*IF(('1_입력값'!$D$16/100)=0,A15,((1+('1_입력값'!$D$16/100))^A15-1)/('1_입력값'!$D$16/100))+'8_시공전후'!D13*A15-('11_인센티브'!B$24+'11_인센티브'!B$25*MIN(A15,'11_인센티브'!$B$12)+'11_인센티브'!B$26*MIN(A15,'11_인센티브'!$B$15)) | D15: ='7_공사비'!D14+'8_시공전후'!E11*IF(('1_입력값'!$D$16/100)=0,A15,((1+('1_입력값'!$D$16/100))^A15-1)/('1_입력값'!$D$16/100))+'8_시공전후'!E13*A15-('11_인센티브'!C$24+'11_인센티브'!C$25*MIN(A15,'11_인센티브'!$B$12)+'11_인센티브'!C$26*MIN(A15,'11_인센티브'!$B$15)) | E15: ='7_공사비'!E14+'8_시공전후'!F11*IF(('1_입력값'!$D$16/100)=0,A15,((1+('1_입력값'!$D$16/100))^A15-1)/('1_입력값'!$D$16/100))+'8_시공전후'!F13*A15-('11_인센티브'!D$24+'11_인센티브'!D$25*MIN(A15,'11_인센티브'!$B$12)+'11_인센티브'!D$26*MIN(A15,'11_인센티브'!$B$15)) | F15: =IF(C15<=B15,A15,"") | G15: =IF(D15<=B15,A15,"") | H15: =IF(E15<=B15,A15,"")
A16: 12 | B16: ='8_시공전후'!C11*IF(('1_입력값'!$D$16/100)=0,A16,((1+('1_입력값'!$D$16/100))^A16-1)/('1_입력값'!$D$16/100)) | C16: ='7_공사비'!C14+'8_시공전후'!D11*IF(('1_입력값'!$D$16/100)=0,A16,((1+('1_입력값'!$D$16/100))^A16-1)/('1_입력값'!$D$16/100))+'8_시공전후'!D13*A16-('11_인센티브'!B$24+'11_인센티브'!B$25*MIN(A16,'11_인센티브'!$B$12)+'11_인센티브'!B$26*MIN(A16,'11_인센티브'!$B$15)) | D16: ='7_공사비'!D14+'8_시공전후'!E11*IF(('1_입력값'!$D$16/100)=0,A16,((1+('1_입력값'!$D$16/100))^A16-1)/('1_입력값'!$D$16/100))+'8_시공전후'!E13*A16-('11_인센티브'!C$24+'11_인센티브'!C$25*MIN(A16,'11_인센티브'!$B$12)+'11_인센티브'!C$26*MIN(A16,'11_인센티브'!$B$15)) | E16: ='7_공사비'!E14+'8_시공전후'!F11*IF(('1_입력값'!$D$16/100)=0,A16,((1+('1_입력값'!$D$16/100))^A16-1)/('1_입력값'!$D$16/100))+'8_시공전후'!F13*A16-('11_인센티브'!D$24+'11_인센티브'!D$25*MIN(A16,'11_인센티브'!$B$12)+'11_인센티브'!D$26*MIN(A16,'11_인센티브'!$B$15)) | F16: =IF(C16<=B16,A16,"") | G16: =IF(D16<=B16,A16,"") | H16: =IF(E16<=B16,A16,"")
A17: 13 | B17: ='8_시공전후'!C11*IF(('1_입력값'!$D$16/100)=0,A17,((1+('1_입력값'!$D$16/100))^A17-1)/('1_입력값'!$D$16/100)) | C17: ='7_공사비'!C14+'8_시공전후'!D11*IF(('1_입력값'!$D$16/100)=0,A17,((1+('1_입력값'!$D$16/100))^A17-1)/('1_입력값'!$D$16/100))+'8_시공전후'!D13*A17-('11_인센티브'!B$24+'11_인센티브'!B$25*MIN(A17,'11_인센티브'!$B$12)+'11_인센티브'!B$26*MIN(A17,'11_인센티브'!$B$15)) | D17: ='7_공사비'!D14+'8_시공전후'!E11*IF(('1_입력값'!$D$16/100)=0,A17,((1+('1_입력값'!$D$16/100))^A17-1)/('1_입력값'!$D$16/100))+'8_시공전후'!E13*A17-('11_인센티브'!C$24+'11_인센티브'!C$25*MIN(A17,'11_인센티브'!$B$12)+'11_인센티브'!C$26*MIN(A17,'11_인센티브'!$B$15)) | E17: ='7_공사비'!E14+'8_시공전후'!F11*IF(('1_입력값'!$D$16/100)=0,A17,((1+('1_입력값'!$D$16/100))^A17-1)/('1_입력값'!$D$16/100))+'8_시공전후'!F13*A17-('11_인센티브'!D$24+'11_인센티브'!D$25*MIN(A17,'11_인센티브'!$B$12)+'11_인센티브'!D$26*MIN(A17,'11_인센티브'!$B$15)) | F17: =IF(C17<=B17,A17,"") | G17: =IF(D17<=B17,A17,"") | H17: =IF(E17<=B17,A17,"")
A18: 14 | B18: ='8_시공전후'!C11*IF(('1_입력값'!$D$16/100)=0,A18,((1+('1_입력값'!$D$16/100))^A18-1)/('1_입력값'!$D$16/100)) | C18: ='7_공사비'!C14+'8_시공전후'!D11*IF(('1_입력값'!$D$16/100)=0,A18,((1+('1_입력값'!$D$16/100))^A18-1)/('1_입력값'!$D$16/100))+'8_시공전후'!D13*A18-('11_인센티브'!B$24+'11_인센티브'!B$25*MIN(A18,'11_인센티브'!$B$12)+'11_인센티브'!B$26*MIN(A18,'11_인센티브'!$B$15)) | D18: ='7_공사비'!D14+'8_시공전후'!E11*IF(('1_입력값'!$D$16/100)=0,A18,((1+('1_입력값'!$D$16/100))^A18-1)/('1_입력값'!$D$16/100))+'8_시공전후'!E13*A18-('11_인센티브'!C$24+'11_인센티브'!C$25*MIN(A18,'11_인센티브'!$B$12)+'11_인센티브'!C$26*MIN(A18,'11_인센티브'!$B$15)) | E18: ='7_공사비'!E14+'8_시공전후'!F11*IF(('1_입력값'!$D$16/100)=0,A18,((1+('1_입력값'!$D$16/100))^A18-1)/('1_입력값'!$D$16/100))+'8_시공전후'!F13*A18-('11_인센티브'!D$24+'11_인센티브'!D$25*MIN(A18,'11_인센티브'!$B$12)+'11_인센티브'!D$26*MIN(A18,'11_인센티브'!$B$15)) | F18: =IF(C18<=B18,A18,"") | G18: =IF(D18<=B18,A18,"") | H18: =IF(E18<=B18,A18,"")
A19: 15 | B19: ='8_시공전후'!C11*IF(('1_입력값'!$D$16/100)=0,A19,((1+('1_입력값'!$D$16/100))^A19-1)/('1_입력값'!$D$16/100)) | C19: ='7_공사비'!C14+'8_시공전후'!D11*IF(('1_입력값'!$D$16/100)=0,A19,((1+('1_입력값'!$D$16/100))^A19-1)/('1_입력값'!$D$16/100))+'8_시공전후'!D13*A19-('11_인센티브'!B$24+'11_인센티브'!B$25*MIN(A19,'11_인센티브'!$B$12)+'11_인센티브'!B$26*MIN(A19,'11_인센티브'!$B$15)) | D19: ='7_공사비'!D14+'8_시공전후'!E11*IF(('1_입력값'!$D$16/100)=0,A19,((1+('1_입력값'!$D$16/100))^A19-1)/('1_입력값'!$D$16/100))+'8_시공전후'!E13*A19-('11_인센티브'!C$24+'11_인센티브'!C$25*MIN(A19,'11_인센티브'!$B$12)+'11_인센티브'!C$26*MIN(A19,'11_인센티브'!$B$15)) | E19: ='7_공사비'!E14+'8_시공전후'!F11*IF(('1_입력값'!$D$16/100)=0,A19,((1+('1_입력값'!$D$16/100))^A19-1)/('1_입력값'!$D$16/100))+'8_시공전후'!F13*A19-('11_인센티브'!D$24+'11_인센티브'!D$25*MIN(A19,'11_인센티브'!$B$12)+'11_인센티브'!D$26*MIN(A19,'11_인센티브'!$B$15)) | F19: =IF(C19<=B19,A19,"") | G19: =IF(D19<=B19,A19,"") | H19: =IF(E19<=B19,A19,"")
A20: 16 | B20: ='8_시공전후'!C11*IF(('1_입력값'!$D$16/100)=0,A20,((1+('1_입력값'!$D$16/100))^A20-1)/('1_입력값'!$D$16/100)) | C20: ='7_공사비'!C14+'8_시공전후'!D11*IF(('1_입력값'!$D$16/100)=0,A20,((1+('1_입력값'!$D$16/100))^A20-1)/('1_입력값'!$D$16/100))+'8_시공전후'!D13*A20-('11_인센티브'!B$24+'11_인센티브'!B$25*MIN(A20,'11_인센티브'!$B$12)+'11_인센티브'!B$26*MIN(A20,'11_인센티브'!$B$15)) | D20: ='7_공사비'!D14+'8_시공전후'!E11*IF(('1_입력값'!$D$16/100)=0,A20,((1+('1_입력값'!$D$16/100))^A20-1)/('1_입력값'!$D$16/100))+'8_시공전후'!E13*A20-('11_인센티브'!C$24+'11_인센티브'!C$25*MIN(A20,'11_인센티브'!$B$12)+'11_인센티브'!C$26*MIN(A20,'11_인센티브'!$B$15)) | E20: ='7_공사비'!E14+'8_시공전후'!F11*IF(('1_입력값'!$D$16/100)=0,A20,((1+('1_입력값'!$D$16/100))^A20-1)/('1_입력값'!$D$16/100))+'8_시공전후'!F13*A20-('11_인센티브'!D$24+'11_인센티브'!D$25*MIN(A20,'11_인센티브'!$B$12)+'11_인센티브'!D$26*MIN(A20,'11_인센티브'!$B$15)) | F20: =IF(C20<=B20,A20,"") | G20: =IF(D20<=B20,A20,"") | H20: =IF(E20<=B20,A20,"")
A21: 17 | B21: ='8_시공전후'!C11*IF(('1_입력값'!$D$16/100)=0,A21,((1+('1_입력값'!$D$16/100))^A21-1)/('1_입력값'!$D$16/100)) | C21: ='7_공사비'!C14+'8_시공전후'!D11*IF(('1_입력값'!$D$16/100)=0,A21,((1+('1_입력값'!$D$16/100))^A21-1)/('1_입력값'!$D$16/100))+'8_시공전후'!D13*A21-('11_인센티브'!B$24+'11_인센티브'!B$25*MIN(A21,'11_인센티브'!$B$12)+'11_인센티브'!B$26*MIN(A21,'11_인센티브'!$B$15)) | D21: ='7_공사비'!D14+'8_시공전후'!E11*IF(('1_입력값'!$D$16/100)=0,A21,((1+('1_입력값'!$D$16/100))^A21-1)/('1_입력값'!$D$16/100))+'8_시공전후'!E13*A21-('11_인센티브'!C$24+'11_인센티브'!C$25*MIN(A21,'11_인센티브'!$B$12)+'11_인센티브'!C$26*MIN(A21,'11_인센티브'!$B$15)) | E21: ='7_공사비'!E14+'8_시공전후'!F11*IF(('1_입력값'!$D$16/100)=0,A21,((1+('1_입력값'!$D$16/100))^A21-1)/('1_입력값'!$D$16/100))+'8_시공전후'!F13*A21-('11_인센티브'!D$24+'11_인센티브'!D$25*MIN(A21,'11_인센티브'!$B$12)+'11_인센티브'!D$26*MIN(A21,'11_인센티브'!$B$15)) | F21: =IF(C21<=B21,A21,"") | G21: =IF(D21<=B21,A21,"") | H21: =IF(E21<=B21,A21,"")
A22: 18 | B22: ='8_시공전후'!C11*IF(('1_입력값'!$D$16/100)=0,A22,((1+('1_입력값'!$D$16/100))^A22-1)/('1_입력값'!$D$16/100)) | C22: ='7_공사비'!C14+'8_시공전후'!D11*IF(('1_입력값'!$D$16/100)=0,A22,((1+('1_입력값'!$D$16/100))^A22-1)/('1_입력값'!$D$16/100))+'8_시공전후'!D13*A22-('11_인센티브'!B$24+'11_인센티브'!B$25*MIN(A22,'11_인센티브'!$B$12)+'11_인센티브'!B$26*MIN(A22,'11_인센티브'!$B$15)) | D22: ='7_공사비'!D14+'8_시공전후'!E11*IF(('1_입력값'!$D$16/100)=0,A22,((1+('1_입력값'!$D$16/100))^A22-1)/('1_입력값'!$D$16/100))+'8_시공전후'!E13*A22-('11_인센티브'!C$24+'11_인센티브'!C$25*MIN(A22,'11_인센티브'!$B$12)+'11_인센티브'!C$26*MIN(A22,'11_인센티브'!$B$15)) | E22: ='7_공사비'!E14+'8_시공전후'!F11*IF(('1_입력값'!$D$16/100)=0,A22,((1+('1_입력값'!$D$16/100))^A22-1)/('1_입력값'!$D$16/100))+'8_시공전후'!F13*A22-('11_인센티브'!D$24+'11_인센티브'!D$25*MIN(A22,'11_인센티브'!$B$12)+'11_인센티브'!D$26*MIN(A22,'11_인센티브'!$B$15)) | F22: =IF(C22<=B22,A22,"") | G22: =IF(D22<=B22,A22,"") | H22: =IF(E22<=B22,A22,"")
A23: 19 | B23: ='8_시공전후'!C11*IF(('1_입력값'!$D$16/100)=0,A23,((1+('1_입력값'!$D$16/100))^A23-1)/('1_입력값'!$D$16/100)) | C23: ='7_공사비'!C14+'8_시공전후'!D11*IF(('1_입력값'!$D$16/100)=0,A23,((1+('1_입력값'!$D$16/100))^A23-1)/('1_입력값'!$D$16/100))+'8_시공전후'!D13*A23-('11_인센티브'!B$24+'11_인센티브'!B$25*MIN(A23,'11_인센티브'!$B$12)+'11_인센티브'!B$26*MIN(A23,'11_인센티브'!$B$15)) | D23: ='7_공사비'!D14+'8_시공전후'!E11*IF(('1_입력값'!$D$16/100)=0,A23,((1+('1_입력값'!$D$16/100))^A23-1)/('1_입력값'!$D$16/100))+'8_시공전후'!E13*A23-('11_인센티브'!C$24+'11_인센티브'!C$25*MIN(A23,'11_인센티브'!$B$12)+'11_인센티브'!C$26*MIN(A23,'11_인센티브'!$B$15)) | E23: ='7_공사비'!E14+'8_시공전후'!F11*IF(('1_입력값'!$D$16/100)=0,A23,((1+('1_입력값'!$D$16/100))^A23-1)/('1_입력값'!$D$16/100))+'8_시공전후'!F13*A23-('11_인센티브'!D$24+'11_인센티브'!D$25*MIN(A23,'11_인센티브'!$B$12)+'11_인센티브'!D$26*MIN(A23,'11_인센티브'!$B$15)) | F23: =IF(C23<=B23,A23,"") | G23: =IF(D23<=B23,A23,"") | H23: =IF(E23<=B23,A23,"")
A24: 20 | B24: ='8_시공전후'!C11*IF(('1_입력값'!$D$16/100)=0,A24,((1+('1_입력값'!$D$16/100))^A24-1)/('1_입력값'!$D$16/100)) | C24: ='7_공사비'!C14+'8_시공전후'!D11*IF(('1_입력값'!$D$16/100)=0,A24,((1+('1_입력값'!$D$16/100))^A24-1)/('1_입력값'!$D$16/100))+'8_시공전후'!D13*A24-('11_인센티브'!B$24+'11_인센티브'!B$25*MIN(A24,'11_인센티브'!$B$12)+'11_인센티브'!B$26*MIN(A24,'11_인센티브'!$B$15)) | D24: ='7_공사비'!D14+'8_시공전후'!E11*IF(('1_입력값'!$D$16/100)=0,A24,((1+('1_입력값'!$D$16/100))^A24-1)/('1_입력값'!$D$16/100))+'8_시공전후'!E13*A24-('11_인센티브'!C$24+'11_인센티브'!C$25*MIN(A24,'11_인센티브'!$B$12)+'11_인센티브'!C$26*MIN(A24,'11_인센티브'!$B$15)) | E24: ='7_공사비'!E14+'8_시공전후'!F11*IF(('1_입력값'!$D$16/100)=0,A24,((1+('1_입력값'!$D$16/100))^A24-1)/('1_입력값'!$D$16/100))+'8_시공전후'!F13*A24-('11_인센티브'!D$24+'11_인센티브'!D$25*MIN(A24,'11_인센티브'!$B$12)+'11_인센티브'!D$26*MIN(A24,'11_인센티브'!$B$15)) | F24: =IF(C24<=B24,A24,"") | G24: =IF(D24<=B24,A24,"") | H24: =IF(E24<=B24,A24,"")
A25: 21 | B25: ='8_시공전후'!C11*IF(('1_입력값'!$D$16/100)=0,A25,((1+('1_입력값'!$D$16/100))^A25-1)/('1_입력값'!$D$16/100)) | C25: ='7_공사비'!C14+'8_시공전후'!D11*IF(('1_입력값'!$D$16/100)=0,A25,((1+('1_입력값'!$D$16/100))^A25-1)/('1_입력값'!$D$16/100))+'8_시공전후'!D13*A25-('11_인센티브'!B$24+'11_인센티브'!B$25*MIN(A25,'11_인센티브'!$B$12)+'11_인센티브'!B$26*MIN(A25,'11_인센티브'!$B$15)) | D25: ='7_공사비'!D14+'8_시공전후'!E11*IF(('1_입력값'!$D$16/100)=0,A25,((1+('1_입력값'!$D$16/100))^A25-1)/('1_입력값'!$D$16/100))+'8_시공전후'!E13*A25-('11_인센티브'!C$24+'11_인센티브'!C$25*MIN(A25,'11_인센티브'!$B$12)+'11_인센티브'!C$26*MIN(A25,'11_인센티브'!$B$15)) | E25: ='7_공사비'!E14+'8_시공전후'!F11*IF(('1_입력값'!$D$16/100)=0,A25,((1+('1_입력값'!$D$16/100))^A25-1)/('1_입력값'!$D$16/100))+'8_시공전후'!F13*A25-('11_인센티브'!D$24+'11_인센티브'!D$25*MIN(A25,'11_인센티브'!$B$12)+'11_인센티브'!D$26*MIN(A25,'11_인센티브'!$B$15)) | F25: =IF(C25<=B25,A25,"") | G25: =IF(D25<=B25,A25,"") | H25: =IF(E25<=B25,A25,"")
A26: 22 | B26: ='8_시공전후'!C11*IF(('1_입력값'!$D$16/100)=0,A26,((1+('1_입력값'!$D$16/100))^A26-1)/('1_입력값'!$D$16/100)) | C26: ='7_공사비'!C14+'8_시공전후'!D11*IF(('1_입력값'!$D$16/100)=0,A26,((1+('1_입력값'!$D$16/100))^A26-1)/('1_입력값'!$D$16/100))+'8_시공전후'!D13*A26-('11_인센티브'!B$24+'11_인센티브'!B$25*MIN(A26,'11_인센티브'!$B$12)+'11_인센티브'!B$26*MIN(A26,'11_인센티브'!$B$15)) | D26: ='7_공사비'!D14+'8_시공전후'!E11*IF(('1_입력값'!$D$16/100)=0,A26,((1+('1_입력값'!$D$16/100))^A26-1)/('1_입력값'!$D$16/100))+'8_시공전후'!E13*A26-('11_인센티브'!C$24+'11_인센티브'!C$25*MIN(A26,'11_인센티브'!$B$12)+'11_인센티브'!C$26*MIN(A26,'11_인센티브'!$B$15)) | E26: ='7_공사비'!E14+'8_시공전후'!F11*IF(('1_입력값'!$D$16/100)=0,A26,((1+('1_입력값'!$D$16/100))^A26-1)/('1_입력값'!$D$16/100))+'8_시공전후'!F13*A26-('11_인센티브'!D$24+'11_인센티브'!D$25*MIN(A26,'11_인센티브'!$B$12)+'11_인센티브'!D$26*MIN(A26,'11_인센티브'!$B$15)) | F26: =IF(C26<=B26,A26,"") | G26: =IF(D26<=B26,A26,"") | H26: =IF(E26<=B26,A26,"")
A27: 23 | B27: ='8_시공전후'!C11*IF(('1_입력값'!$D$16/100)=0,A27,((1+('1_입력값'!$D$16/100))^A27-1)/('1_입력값'!$D$16/100)) | C27: ='7_공사비'!C14+'8_시공전후'!D11*IF(('1_입력값'!$D$16/100)=0,A27,((1+('1_입력값'!$D$16/100))^A27-1)/('1_입력값'!$D$16/100))+'8_시공전후'!D13*A27-('11_인센티브'!B$24+'11_인센티브'!B$25*MIN(A27,'11_인센티브'!$B$12)+'11_인센티브'!B$26*MIN(A27,'11_인센티브'!$B$15)) | D27: ='7_공사비'!D14+'8_시공전후'!E11*IF(('1_입력값'!$D$16/100)=0,A27,((1+('1_입력값'!$D$16/100))^A27-1)/('1_입력값'!$D$16/100))+'8_시공전후'!E13*A27-('11_인센티브'!C$24+'11_인센티브'!C$25*MIN(A27,'11_인센티브'!$B$12)+'11_인센티브'!C$26*MIN(A27,'11_인센티브'!$B$15)) | E27: ='7_공사비'!E14+'8_시공전후'!F11*IF(('1_입력값'!$D$16/100)=0,A27,((1+('1_입력값'!$D$16/100))^A27-1)/('1_입력값'!$D$16/100))+'8_시공전후'!F13*A27-('11_인센티브'!D$24+'11_인센티브'!D$25*MIN(A27,'11_인센티브'!$B$12)+'11_인센티브'!D$26*MIN(A27,'11_인센티브'!$B$15)) | F27: =IF(C27<=B27,A27,"") | G27: =IF(D27<=B27,A27,"") | H27: =IF(E27<=B27,A27,"")
A28: 24 | B28: ='8_시공전후'!C11*IF(('1_입력값'!$D$16/100)=0,A28,((1+('1_입력값'!$D$16/100))^A28-1)/('1_입력값'!$D$16/100)) | C28: ='7_공사비'!C14+'8_시공전후'!D11*IF(('1_입력값'!$D$16/100)=0,A28,((1+('1_입력값'!$D$16/100))^A28-1)/('1_입력값'!$D$16/100))+'8_시공전후'!D13*A28-('11_인센티브'!B$24+'11_인센티브'!B$25*MIN(A28,'11_인센티브'!$B$12)+'11_인센티브'!B$26*MIN(A28,'11_인센티브'!$B$15)) | D28: ='7_공사비'!D14+'8_시공전후'!E11*IF(('1_입력값'!$D$16/100)=0,A28,((1+('1_입력값'!$D$16/100))^A28-1)/('1_입력값'!$D$16/100))+'8_시공전후'!E13*A28-('11_인센티브'!C$24+'11_인센티브'!C$25*MIN(A28,'11_인센티브'!$B$12)+'11_인센티브'!C$26*MIN(A28,'11_인센티브'!$B$15)) | E28: ='7_공사비'!E14+'8_시공전후'!F11*IF(('1_입력값'!$D$16/100)=0,A28,((1+('1_입력값'!$D$16/100))^A28-1)/('1_입력값'!$D$16/100))+'8_시공전후'!F13*A28-('11_인센티브'!D$24+'11_인센티브'!D$25*MIN(A28,'11_인센티브'!$B$12)+'11_인센티브'!D$26*MIN(A28,'11_인센티브'!$B$15)) | F28: =IF(C28<=B28,A28,"") | G28: =IF(D28<=B28,A28,"") | H28: =IF(E28<=B28,A28,"")
A29: 25 | B29: ='8_시공전후'!C11*IF(('1_입력값'!$D$16/100)=0,A29,((1+('1_입력값'!$D$16/100))^A29-1)/('1_입력값'!$D$16/100)) | C29: ='7_공사비'!C14+'8_시공전후'!D11*IF(('1_입력값'!$D$16/100)=0,A29,((1+('1_입력값'!$D$16/100))^A29-1)/('1_입력값'!$D$16/100))+'8_시공전후'!D13*A29-('11_인센티브'!B$24+'11_인센티브'!B$25*MIN(A29,'11_인센티브'!$B$12)+'11_인센티브'!B$26*MIN(A29,'11_인센티브'!$B$15)) | D29: ='7_공사비'!D14+'8_시공전후'!E11*IF(('1_입력값'!$D$16/100)=0,A29,((1+('1_입력값'!$D$16/100))^A29-1)/('1_입력값'!$D$16/100))+'8_시공전후'!E13*A29-('11_인센티브'!C$24+'11_인센티브'!C$25*MIN(A29,'11_인센티브'!$B$12)+'11_인센티브'!C$26*MIN(A29,'11_인센티브'!$B$15)) | E29: ='7_공사비'!E14+'8_시공전후'!F11*IF(('1_입력값'!$D$16/100)=0,A29,((1+('1_입력값'!$D$16/100))^A29-1)/('1_입력값'!$D$16/100))+'8_시공전후'!F13*A29-('11_인센티브'!D$24+'11_인센티브'!D$25*MIN(A29,'11_인센티브'!$B$12)+'11_인센티브'!D$26*MIN(A29,'11_인센티브'!$B$15)) | F29: =IF(C29<=B29,A29,"") | G29: =IF(D29<=B29,A29,"") | H29: =IF(E29<=B29,A29,"")
A30: 26 | B30: ='8_시공전후'!C11*IF(('1_입력값'!$D$16/100)=0,A30,((1+('1_입력값'!$D$16/100))^A30-1)/('1_입력값'!$D$16/100)) | C30: ='7_공사비'!C14+'8_시공전후'!D11*IF(('1_입력값'!$D$16/100)=0,A30,((1+('1_입력값'!$D$16/100))^A30-1)/('1_입력값'!$D$16/100))+'8_시공전후'!D13*A30-('11_인센티브'!B$24+'11_인센티브'!B$25*MIN(A30,'11_인센티브'!$B$12)+'11_인센티브'!B$26*MIN(A30,'11_인센티브'!$B$15)) | D30: ='7_공사비'!D14+'8_시공전후'!E11*IF(('1_입력값'!$D$16/100)=0,A30,((1+('1_입력값'!$D$16/100))^A30-1)/('1_입력값'!$D$16/100))+'8_시공전후'!E13*A30-('11_인센티브'!C$24+'11_인센티브'!C$25*MIN(A30,'11_인센티브'!$B$12)+'11_인센티브'!C$26*MIN(A30,'11_인센티브'!$B$15)) | E30: ='7_공사비'!E14+'8_시공전후'!F11*IF(('1_입력값'!$D$16/100)=0,A30,((1+('1_입력값'!$D$16/100))^A30-1)/('1_입력값'!$D$16/100))+'8_시공전후'!F13*A30-('11_인센티브'!D$24+'11_인센티브'!D$25*MIN(A30,'11_인센티브'!$B$12)+'11_인센티브'!D$26*MIN(A30,'11_인센티브'!$B$15)) | F30: =IF(C30<=B30,A30,"") | G30: =IF(D30<=B30,A30,"") | H30: =IF(E30<=B30,A30,"")
A31: 27 | B31: ='8_시공전후'!C11*IF(('1_입력값'!$D$16/100)=0,A31,((1+('1_입력값'!$D$16/100))^A31-1)/('1_입력값'!$D$16/100)) | C31: ='7_공사비'!C14+'8_시공전후'!D11*IF(('1_입력값'!$D$16/100)=0,A31,((1+('1_입력값'!$D$16/100))^A31-1)/('1_입력값'!$D$16/100))+'8_시공전후'!D13*A31-('11_인센티브'!B$24+'11_인센티브'!B$25*MIN(A31,'11_인센티브'!$B$12)+'11_인센티브'!B$26*MIN(A31,'11_인센티브'!$B$15)) | D31: ='7_공사비'!D14+'8_시공전후'!E11*IF(('1_입력값'!$D$16/100)=0,A31,((1+('1_입력값'!$D$16/100))^A31-1)/('1_입력값'!$D$16/100))+'8_시공전후'!E13*A31-('11_인센티브'!C$24+'11_인센티브'!C$25*MIN(A31,'11_인센티브'!$B$12)+'11_인센티브'!C$26*MIN(A31,'11_인센티브'!$B$15)) | E31: ='7_공사비'!E14+'8_시공전후'!F11*IF(('1_입력값'!$D$16/100)=0,A31,((1+('1_입력값'!$D$16/100))^A31-1)/('1_입력값'!$D$16/100))+'8_시공전후'!F13*A31-('11_인센티브'!D$24+'11_인센티브'!D$25*MIN(A31,'11_인센티브'!$B$12)+'11_인센티브'!D$26*MIN(A31,'11_인센티브'!$B$15)) | F31: =IF(C31<=B31,A31,"") | G31: =IF(D31<=B31,A31,"") | H31: =IF(E31<=B31,A31,"")
A32: 28 | B32: ='8_시공전후'!C11*IF(('1_입력값'!$D$16/100)=0,A32,((1+('1_입력값'!$D$16/100))^A32-1)/('1_입력값'!$D$16/100)) | C32: ='7_공사비'!C14+'8_시공전후'!D11*IF(('1_입력값'!$D$16/100)=0,A32,((1+('1_입력값'!$D$16/100))^A32-1)/('1_입력값'!$D$16/100))+'8_시공전후'!D13*A32-('11_인센티브'!B$24+'11_인센티브'!B$25*MIN(A32,'11_인센티브'!$B$12)+'11_인센티브'!B$26*MIN(A32,'11_인센티브'!$B$15)) | D32: ='7_공사비'!D14+'8_시공전후'!E11*IF(('1_입력값'!$D$16/100)=0,A32,((1+('1_입력값'!$D$16/100))^A32-1)/('1_입력값'!$D$16/100))+'8_시공전후'!E13*A32-('11_인센티브'!C$24+'11_인센티브'!C$25*MIN(A32,'11_인센티브'!$B$12)+'11_인센티브'!C$26*MIN(A32,'11_인센티브'!$B$15)) | E32: ='7_공사비'!E14+'8_시공전후'!F11*IF(('1_입력값'!$D$16/100)=0,A32,((1+('1_입력값'!$D$16/100))^A32-1)/('1_입력값'!$D$16/100))+'8_시공전후'!F13*A32-('11_인센티브'!D$24+'11_인센티브'!D$25*MIN(A32,'11_인센티브'!$B$12)+'11_인센티브'!D$26*MIN(A32,'11_인센티브'!$B$15)) | F32: =IF(C32<=B32,A32,"") | G32: =IF(D32<=B32,A32,"") | H32: =IF(E32<=B32,A32,"")
A33: 29 | B33: ='8_시공전후'!C11*IF(('1_입력값'!$D$16/100)=0,A33,((1+('1_입력값'!$D$16/100))^A33-1)/('1_입력값'!$D$16/100)) | C33: ='7_공사비'!C14+'8_시공전후'!D11*IF(('1_입력값'!$D$16/100)=0,A33,((1+('1_입력값'!$D$16/100))^A33-1)/('1_입력값'!$D$16/100))+'8_시공전후'!D13*A33-('11_인센티브'!B$24+'11_인센티브'!B$25*MIN(A33,'11_인센티브'!$B$12)+'11_인센티브'!B$26*MIN(A33,'11_인센티브'!$B$15)) | D33: ='7_공사비'!D14+'8_시공전후'!E11*IF(('1_입력값'!$D$16/100)=0,A33,((1+('1_입력값'!$D$16/100))^A33-1)/('1_입력값'!$D$16/100))+'8_시공전후'!E13*A33-('11_인센티브'!C$24+'11_인센티브'!C$25*MIN(A33,'11_인센티브'!$B$12)+'11_인센티브'!C$26*MIN(A33,'11_인센티브'!$B$15)) | E33: ='7_공사비'!E14+'8_시공전후'!F11*IF(('1_입력값'!$D$16/100)=0,A33,((1+('1_입력값'!$D$16/100))^A33-1)/('1_입력값'!$D$16/100))+'8_시공전후'!F13*A33-('11_인센티브'!D$24+'11_인센티브'!D$25*MIN(A33,'11_인센티브'!$B$12)+'11_인센티브'!D$26*MIN(A33,'11_인센티브'!$B$15)) | F33: =IF(C33<=B33,A33,"") | G33: =IF(D33<=B33,A33,"") | H33: =IF(E33<=B33,A33,"")
A34: 30 | B34: ='8_시공전후'!C11*IF(('1_입력값'!$D$16/100)=0,A34,((1+('1_입력값'!$D$16/100))^A34-1)/('1_입력값'!$D$16/100)) | C34: ='7_공사비'!C14+'8_시공전후'!D11*IF(('1_입력값'!$D$16/100)=0,A34,((1+('1_입력값'!$D$16/100))^A34-1)/('1_입력값'!$D$16/100))+'8_시공전후'!D13*A34-('11_인센티브'!B$24+'11_인센티브'!B$25*MIN(A34,'11_인센티브'!$B$12)+'11_인센티브'!B$26*MIN(A34,'11_인센티브'!$B$15)) | D34: ='7_공사비'!D14+'8_시공전후'!E11*IF(('1_입력값'!$D$16/100)=0,A34,((1+('1_입력값'!$D$16/100))^A34-1)/('1_입력값'!$D$16/100))+'8_시공전후'!E13*A34-('11_인센티브'!C$24+'11_인센티브'!C$25*MIN(A34,'11_인센티브'!$B$12)+'11_인센티브'!C$26*MIN(A34,'11_인센티브'!$B$15)) | E34: ='7_공사비'!E14+'8_시공전후'!F11*IF(('1_입력값'!$D$16/100)=0,A34,((1+('1_입력값'!$D$16/100))^A34-1)/('1_입력값'!$D$16/100))+'8_시공전후'!F13*A34-('11_인센티브'!D$24+'11_인센티브'!D$25*MIN(A34,'11_인센티브'!$B$12)+'11_인센티브'!D$26*MIN(A34,'11_인센티브'!$B$15)) | F34: =IF(C34<=B34,A34,"") | G34: =IF(D34<=B34,A34,"") | H34: =IF(E34<=B34,A34,"")
A35: 31 | B35: ='8_시공전후'!C11*IF(('1_입력값'!$D$16/100)=0,A35,((1+('1_입력값'!$D$16/100))^A35-1)/('1_입력값'!$D$16/100)) | C35: ='7_공사비'!C14+'8_시공전후'!D11*IF(('1_입력값'!$D$16/100)=0,A35,((1+('1_입력값'!$D$16/100))^A35-1)/('1_입력값'!$D$16/100))+'8_시공전후'!D13*A35-('11_인센티브'!B$24+'11_인센티브'!B$25*MIN(A35,'11_인센티브'!$B$12)+'11_인센티브'!B$26*MIN(A35,'11_인센티브'!$B$15)) | D35: ='7_공사비'!D14+'8_시공전후'!E11*IF(('1_입력값'!$D$16/100)=0,A35,((1+('1_입력값'!$D$16/100))^A35-1)/('1_입력값'!$D$16/100))+'8_시공전후'!E13*A35-('11_인센티브'!C$24+'11_인센티브'!C$25*MIN(A35,'11_인센티브'!$B$12)+'11_인센티브'!C$26*MIN(A35,'11_인센티브'!$B$15)) | E35: ='7_공사비'!E14+'8_시공전후'!F11*IF(('1_입력값'!$D$16/100)=0,A35,((1+('1_입력값'!$D$16/100))^A35-1)/('1_입력값'!$D$16/100))+'8_시공전후'!F13*A35-('11_인센티브'!D$24+'11_인센티브'!D$25*MIN(A35,'11_인센티브'!$B$12)+'11_인센티브'!D$26*MIN(A35,'11_인센티브'!$B$15)) | F35: =IF(C35<=B35,A35,"") | G35: =IF(D35<=B35,A35,"") | H35: =IF(E35<=B35,A35,"")
A36: 32 | B36: ='8_시공전후'!C11*IF(('1_입력값'!$D$16/100)=0,A36,((1+('1_입력값'!$D$16/100))^A36-1)/('1_입력값'!$D$16/100)) | C36: ='7_공사비'!C14+'8_시공전후'!D11*IF(('1_입력값'!$D$16/100)=0,A36,((1+('1_입력값'!$D$16/100))^A36-1)/('1_입력값'!$D$16/100))+'8_시공전후'!D13*A36-('11_인센티브'!B$24+'11_인센티브'!B$25*MIN(A36,'11_인센티브'!$B$12)+'11_인센티브'!B$26*MIN(A36,'11_인센티브'!$B$15)) | D36: ='7_공사비'!D14+'8_시공전후'!E11*IF(('1_입력값'!$D$16/100)=0,A36,((1+('1_입력값'!$D$16/100))^A36-1)/('1_입력값'!$D$16/100))+'8_시공전후'!E13*A36-('11_인센티브'!C$24+'11_인센티브'!C$25*MIN(A36,'11_인센티브'!$B$12)+'11_인센티브'!C$26*MIN(A36,'11_인센티브'!$B$15)) | E36: ='7_공사비'!E14+'8_시공전후'!F11*IF(('1_입력값'!$D$16/100)=0,A36,((1+('1_입력값'!$D$16/100))^A36-1)/('1_입력값'!$D$16/100))+'8_시공전후'!F13*A36-('11_인센티브'!D$24+'11_인센티브'!D$25*MIN(A36,'11_인센티브'!$B$12)+'11_인센티브'!D$26*MIN(A36,'11_인센티브'!$B$15)) | F36: =IF(C36<=B36,A36,"") | G36: =IF(D36<=B36,A36,"") | H36: =IF(E36<=B36,A36,"")
A37: 33 | B37: ='8_시공전후'!C11*IF(('1_입력값'!$D$16/100)=0,A37,((1+('1_입력값'!$D$16/100))^A37-1)/('1_입력값'!$D$16/100)) | C37: ='7_공사비'!C14+'8_시공전후'!D11*IF(('1_입력값'!$D$16/100)=0,A37,((1+('1_입력값'!$D$16/100))^A37-1)/('1_입력값'!$D$16/100))+'8_시공전후'!D13*A37-('11_인센티브'!B$24+'11_인센티브'!B$25*MIN(A37,'11_인센티브'!$B$12)+'11_인센티브'!B$26*MIN(A37,'11_인센티브'!$B$15)) | D37: ='7_공사비'!D14+'8_시공전후'!E11*IF(('1_입력값'!$D$16/100)=0,A37,((1+('1_입력값'!$D$16/100))^A37-1)/('1_입력값'!$D$16/100))+'8_시공전후'!E13*A37-('11_인센티브'!C$24+'11_인센티브'!C$25*MIN(A37,'11_인센티브'!$B$12)+'11_인센티브'!C$26*MIN(A37,'11_인센티브'!$B$15)) | E37: ='7_공사비'!E14+'8_시공전후'!F11*IF(('1_입력값'!$D$16/100)=0,A37,((1+('1_입력값'!$D$16/100))^A37-1)/('1_입력값'!$D$16/100))+'8_시공전후'!F13*A37-('11_인센티브'!D$24+'11_인센티브'!D$25*MIN(A37,'11_인센티브'!$B$12)+'11_인센티브'!D$26*MIN(A37,'11_인센티브'!$B$15)) | F37: =IF(C37<=B37,A37,"") | G37: =IF(D37<=B37,A37,"") | H37: =IF(E37<=B37,A37,"")
A38: 34 | B38: ='8_시공전후'!C11*IF(('1_입력값'!$D$16/100)=0,A38,((1+('1_입력값'!$D$16/100))^A38-1)/('1_입력값'!$D$16/100)) | C38: ='7_공사비'!C14+'8_시공전후'!D11*IF(('1_입력값'!$D$16/100)=0,A38,((1+('1_입력값'!$D$16/100))^A38-1)/('1_입력값'!$D$16/100))+'8_시공전후'!D13*A38-('11_인센티브'!B$24+'11_인센티브'!B$25*MIN(A38,'11_인센티브'!$B$12)+'11_인센티브'!B$26*MIN(A38,'11_인센티브'!$B$15)) | D38: ='7_공사비'!D14+'8_시공전후'!E11*IF(('1_입력값'!$D$16/100)=0,A38,((1+('1_입력값'!$D$16/100))^A38-1)/('1_입력값'!$D$16/100))+'8_시공전후'!E13*A38-('11_인센티브'!C$24+'11_인센티브'!C$25*MIN(A38,'11_인센티브'!$B$12)+'11_인센티브'!C$26*MIN(A38,'11_인센티브'!$B$15)) | E38: ='7_공사비'!E14+'8_시공전후'!F11*IF(('1_입력값'!$D$16/100)=0,A38,((1+('1_입력값'!$D$16/100))^A38-1)/('1_입력값'!$D$16/100))+'8_시공전후'!F13*A38-('11_인센티브'!D$24+'11_인센티브'!D$25*MIN(A38,'11_인센티브'!$B$12)+'11_인센티브'!D$26*MIN(A38,'11_인센티브'!$B$15)) | F38: =IF(C38<=B38,A38,"") | G38: =IF(D38<=B38,A38,"") | H38: =IF(E38<=B38,A38,"")
A39: 35 | B39: ='8_시공전후'!C11*IF(('1_입력값'!$D$16/100)=0,A39,((1+('1_입력값'!$D$16/100))^A39-1)/('1_입력값'!$D$16/100)) | C39: ='7_공사비'!C14+'8_시공전후'!D11*IF(('1_입력값'!$D$16/100)=0,A39,((1+('1_입력값'!$D$16/100))^A39-1)/('1_입력값'!$D$16/100))+'8_시공전후'!D13*A39-('11_인센티브'!B$24+'11_인센티브'!B$25*MIN(A39,'11_인센티브'!$B$12)+'11_인센티브'!B$26*MIN(A39,'11_인센티브'!$B$15)) | D39: ='7_공사비'!D14+'8_시공전후'!E11*IF(('1_입력값'!$D$16/100)=0,A39,((1+('1_입력값'!$D$16/100))^A39-1)/('1_입력값'!$D$16/100))+'8_시공전후'!E13*A39-('11_인센티브'!C$24+'11_인센티브'!C$25*MIN(A39,'11_인센티브'!$B$12)+'11_인센티브'!C$26*MIN(A39,'11_인센티브'!$B$15)) | E39: ='7_공사비'!E14+'8_시공전후'!F11*IF(('1_입력값'!$D$16/100)=0,A39,((1+('1_입력값'!$D$16/100))^A39-1)/('1_입력값'!$D$16/100))+'8_시공전후'!F13*A39-('11_인센티브'!D$24+'11_인센티브'!D$25*MIN(A39,'11_인센티브'!$B$12)+'11_인센티브'!D$26*MIN(A39,'11_인센티브'!$B$15)) | F39: =IF(C39<=B39,A39,"") | G39: =IF(D39<=B39,A39,"") | H39: =IF(E39<=B39,A39,"")
A40: 36 | B40: ='8_시공전후'!C11*IF(('1_입력값'!$D$16/100)=0,A40,((1+('1_입력값'!$D$16/100))^A40-1)/('1_입력값'!$D$16/100)) | C40: ='7_공사비'!C14+'8_시공전후'!D11*IF(('1_입력값'!$D$16/100)=0,A40,((1+('1_입력값'!$D$16/100))^A40-1)/('1_입력값'!$D$16/100))+'8_시공전후'!D13*A40-('11_인센티브'!B$24+'11_인센티브'!B$25*MIN(A40,'11_인센티브'!$B$12)+'11_인센티브'!B$26*MIN(A40,'11_인센티브'!$B$15)) | D40: ='7_공사비'!D14+'8_시공전후'!E11*IF(('1_입력값'!$D$16/100)=0,A40,((1+('1_입력값'!$D$16/100))^A40-1)/('1_입력값'!$D$16/100))+'8_시공전후'!E13*A40-('11_인센티브'!C$24+'11_인센티브'!C$25*MIN(A40,'11_인센티브'!$B$12)+'11_인센티브'!C$26*MIN(A40,'11_인센티브'!$B$15)) | E40: ='7_공사비'!E14+'8_시공전후'!F11*IF(('1_입력값'!$D$16/100)=0,A40,((1+('1_입력값'!$D$16/100))^A40-1)/('1_입력값'!$D$16/100))+'8_시공전후'!F13*A40-('11_인센티브'!D$24+'11_인센티브'!D$25*MIN(A40,'11_인센티브'!$B$12)+'11_인센티브'!D$26*MIN(A40,'11_인센티브'!$B$15)) | F40: =IF(C40<=B40,A40,"") | G40: =IF(D40<=B40,A40,"") | H40: =IF(E40<=B40,A40,"")
...

Sheet 11_인센티브
A1: 인증 인센티브 (신축 / 리모델링) — 가정값, 기본은 꺼짐
A2: 에너지효율등급·녹색건축·제로에너지건축물 인증은 건물 전체 성능으로 받습니다. 루버만으로 등급이 오른다는 보장은 없어, 아래는 "인증을 받는다고 가정할 때"의 시나리오입니다. 감면율·기간은 지자체와 시기에 따라 달라 확인이 필요합니다.
A4: 입력 | B4: 값 | C4: 단위 | E4: 설명 · 근거
A5: 인센티브 반영 (1=반영, 0=미반영) | B5: 0 | C5: 스위치 | E5: 0이면 다른 시트에 영향 없음
A6: 시나리오 (신축 / 리모델링) | B6: 신축 | C6: 선택 | E6: 신축: 취득세·재산세 감면 / 리모델링: 이자지원·재산세 감면
A7: 건물 취득가액 (신축) | B7: 20000000000 | C7: 원 | E7: 임시 테스트값. 공사비 총액 기준으로 교체
A8: 취득세율 (신축 원시취득, 부가세 포함) | B8: 3.16 | C8: % | E8: 추정. 지방세법 세율 확인 필요
A9: 취득세 감면율 | B9: 10 | C9: % | E9: 서울시 안내 5~15% (등급별). 출처: 서울시 미디어허브 · 지자체 확인 필요
A10: 연 재산세 (감면 전) | B10: 100000000 | C10: 원/년 | E10: 임시 테스트값
A11: 재산세 감면율 | B11: 9 | C11: % | E11: 서울시 안내 3~15% (등급별)
A12: 재산세 감면 기간 | B12: 5 | C12: 년 | E12: 가정. 지자체 확인 필요
A13: 대출 비율 (공사비 대비, 리모델링) | B13: 70 | C13: % | E13: 가정
A14: 이자지원율 | B14: 3 | C14: % | E14: 가정. 그린리모델링 이자지원은 최대 5.5%로 보도됨(2026). 대상 공사·조건 확인 필요
A15: 이자지원 기간 | B15: 5 | C15: 년 | E15: 가정
A17: 대안별 계산 | B17: 내부 반응형 | C17: 외부 고정 | D17: 외부 반응형 | E17: 설명
A18: 인증 등급 상승 인정 (1/0) | B18: 1 | C18: 1 | D18: 1 | E18: 대안이 건물 등급을 올린다고 가정하면 1
A19: [신축] 취득세 감면 (일시) | B19: =B18*$B$7*$B$8/100*$B$9/100 | C19: =C18*$B$7*$B$8/100*$B$9/100 | D19: =D18*$B$7*$B$8/100*$B$9/100 | E19: 취득가액 × 세율 × 감면율
A20: [공통] 재산세 감면 (연) | B20: =B18*$B$10*$B$11/100 | C20: =C18*$B$10*$B$11/100 | D20: =D18*$B$10*$B$11/100 | E20: 연 재산세 × 감면율
A21: [리모델링] 이자지원 (연) | B21: =B18*'7_공사비'!C14*$B$13/100*$B$14/100 | C21: =C18*'7_공사비'!D14*$B$13/100*$B$14/100 | D21: =D18*'7_공사비'!E14*$B$13/100*$B$14/100 | E21: 총 공사비 × 대출비율 × 지원율
A23: 적용되는 금액 (스위치·시나리오 반영) | B23: 내부 반응형 | C23: 외부 고정 | D23: 외부 반응형 | E23: 다른 시트로 가는 값
A24: 일시 혜택 (공사비 차감 효과) | B24: =IF(AND($B$5=1,$B$6="신축"),B19,0) | C24: =IF(AND($B$5=1,$B$6="신축"),C19,0) | D24: =IF(AND($B$5=1,$B$6="신축"),D19,0)
A25: 재산세 감면 (연, 기간 동안) | B25: =IF($B$5=1,B20,0) | C25: =IF($B$5=1,C20,0) | D25: =IF($B$5=1,D20,0)
A26: 이자지원 (연, 기간 동안) | B26: =IF(AND($B$5=1,$B$6="리모델링"),B21,0) | C26: =IF(AND($B$5=1,$B$6="리모델링"),C21,0) | D26: =IF(AND($B$5=1,$B$6="리모델링"),D21,0)

Sheet 12_일정표
A1: 일차 | B1: 구분 | C1: 할 일 | D1: 담당 | E1: 넘길 것 → 받는 사람 | F1: 판단 지점 | G1: 완료
A2: 1 | B2: 함께·조사 | C2: 공사비 항목별 단가 조사(자재·구동·설치·가설·설계감리) | D2: 은미 | E2: 단가표(출처) → 전원 | G2: ☐
A3: 1 | B3: 함께·조사 | C3: 유지비·수명, 전기요금, 차폐계수·냉방 환산 방법 | D3: 은미 | E3: 결정 메모 → 전원 | G3: ☐
A4: 1 | B4: 함께·조사 | C4: 결정 회의: 입력값 목록, 분석 입면, 대표일, 대안 정의 | D4: 은미 진행 | E4: 결정 메모 → 전원 | G4: ☐
A5: 2 | B5: 함께·틀 | C5: 입력값 시트 + 공사비·시공 전후·발주처 이익 시트 | D5: 은미 | E5: 시트 틀 → 전원 | G5: ☐
A6: 2 | B6: 함께·틀 | C6: 보고서 템플릿 서식, 일정표 공유, 첫 스탠드업 | D6: 은미 | E6: 보고서 템플릿 → 전원 | G6: ☐
A7: 2 | B7: 함께·틀 | C7: 루버 패밀리 파라미터 이름 합의 | D7: 우정·혜연 | E7: 파라미터 이름표 → 은미 참조 | G7: ☐
A8: 3 | B8: 분석·보고서 조 | C8: 단가 확정, 우정 물량으로 공사비 1차 | D8: 은미 | E8: 작동하는 시트 → 전원 | G8: ☐
A9: 3 | B9: 분석·보고서 조 | C9: 저녁 관통에 시트 연결 | D9: 은미·혜연 | G9: ☐
A10: 3 | B10: 분석·보고서 조 | C10: Unity 판단 회의 (모델이 열리고 태양을 날짜·시각으로 움직이나) | D10: 은미 진행(건우·혜연) | E10: Unity 결정 → 전원 | F10: 3일차 저녁 | G10: ☐
A11: 4 | B11: ③ 적용 | C11: 혜연 일사량 → 냉방 전력 환산, 서우 조명 값 반영 | D11: 은미 | G11: ☐
